Workbook
Name AddressOfSite: 'General Information'!$D$404:$D$503
Name AmountOfEmissionsTable: 'Environmental Disclosures'!$D$80:$K$179
Name AmountOfEmissionToAir: 'Environmental Disclosures'!$G$80:$I$179
Name AmountOfEmissionToAir_unit: 'Environmental Disclosures'!$C$78
Name AmountOfEmissionToSoil: 'Environmental Disclosures'!$K$80:$K$179
Name AmountOfEmissionToSoil_unit: 'Environmental Disclosures'!$C$78
Name AmountOfEmissionToWater: 'Environmental Disclosures'!$J$80:$J$179
Name AmountOfEmissionToWater_unit: 'Environmental Disclosures'!$C$78
Name AmountOfWaterWithdrawnAtSitesLocatedInAreasOfHighWaterStress: 'Environmental Disclosures'!$D$304
Name AreaOfSiteInBiodiversitySensitiveArea: 'Environmental Disclosures'!$G$188:$I$287
Name AreaOfSiteInBiodiversitySensitiveArea_unit: 'Environmental Disclosures'!$C$186
Name Assets: 'General Information'!$E$280
Name AverageNumberOfAnnualTrainingHoursPerFemaleEmployee: 'Social Disclosures'!$D$158
Name AverageNumberOfAnnualTrainingHoursPerMaleEmployee: 'Social Disclosures'!$D$157
Name AverageNumberOfAnnualTrainingHoursPerNonReportedGenderEmployee: 'Social Disclosures'!$D$160
Name AverageNumberOfAnnualTrainingHoursPerOtherGenderEmployee: 'Social Disclosures'!$D$159
Name BaselineYearMember: 'Environmental Disclosures'!$G$21
Name BasisForPreparation: 'General Information'!$E$122
Name BasisForReporting: 'General Information'!$E$177
Name BreakdownOfAnnualMassFlowOfRelevantMaterialsUsedByTheUndertakingHypercube: 'Environmental Disclosures'!$C$435:$I$534
Name BreakdownOfEnergyConsumptionAxis: 'Environmental Disclosures'!$C$12:$F$14
Name BreakdownOfEnergyConsumptionTable: 'Environmental Disclosures'!$G$12:$K$14
Name CityOfSite: 'General Information'!$F$404:$F$503
Name CountryOfEmploymentContractAxis: 'Social Disclosures'!$C$29:$D$128
Name CountryOfPrimaryOperationsAndLocationOfSignificantAssets: 'General Information'!$E$285
Name CountryOfSite: 'General Information'!$G$404:$G$503
Name DateOfAdoptionOfTransitionPlanForUndertakingNotHavingAdoptedTransitionPlanYet: 'Environmental Disclosures'!$D$62
Name DescriptionOfActionsTakeToAddressTheConfirmedIncidents: 'Social Disclosures'!$D$192
Name DescriptionOfATargetRelatedToAPolicy: 'General Information'!$E$520
Name DescriptionOfATransitionPlanForClimateChangeMitigationIncludingAnExplanationOfHowItIsContributingToReduceGhgEmissions: 'Environmental Disclosures'!$D$58
Name DescriptionOfClimateRelatedHazardsAndClimateRelatedTransitionEvents: 'Environmental Disclosures'!$E$540
Name DescriptionOfHowCircularEconomyPrinciplesAreApplied: 'Environmental Disclosures'!$D$317
Name DescriptionOfKeyElementsOfStrategyThatRelatesToOrAffectsSustainabilityIssues: 'General Information'!$E$529
Name DescriptionOfLimitsToTheDistributionOfProfitsConnectedToTheMutualisticNatureOrToTheNatureOfTheActivitiesConsistingInServicesOfGeneralEconomicInterestSGEI: 'General Information'!$D$516
Name DescriptionOfMainBusinessRelationships: 'General Information'!$E$527
Name DescriptionOfPracticesPoliciesAndOrFutureInitiatives: 'General Information'!$E$519
Name DescriptionOfSignificantGroupsOfProductsAndOrServicesOffered: 'General Information'!$E$525
Name DescriptionOfSignificantMarketsTheUndertakingOperatesIn: 'General Information'!$E$526
Name DescriptionOfSustainabilityRelatedCertificationsOrLabels: 'General Information'!$E$395
Name DescriptionOfTheEffectiveParticipationOfWorkersUsersOrOtherInterestedPartiesOrCommunitiesInGovernance: 'General Information'!$D$514
Name DisclosureOfAnyOtherEnvironmentalAndOrEntitySpecificEnvironmentalDisclosures: 'Environmental Disclosures'!$C$548
Name DisclosureOfAnyOtherGeneralAndOrEntitySpecificInformation: 'General Information'!$C$533
Name DisclosureOfAnyOtherGovernanceAndOrEntitySpecificGovernanceDisclosures: 'Governance Disclosures'!$C$38
Name DisclosureOfAnyOtherSocialAndOrEntitySpecificSocialDisclosures: 'Social Disclosures'!$C$200
Name DisclosureOfHowItHasAssessedTheExposureAndSensitivityOfItsAssetsActivitiesAndValueChainToTheseHazardsAndTransitionEvents: 'Environmental Disclosures'!$E$541
Name DisclosureOfListOfMainActionsTheEntitySeeksInOrderToAchieveItsTargets: 'Environmental Disclosures'!$C$52
Name DisclosureOfWhetherItHasUndertakenClimateChangeAdaptationActionsForAnyClimateRelatedHazardsAndTransitionEvents: 'Environmental Disclosures'!$E$543
Name EmployeeCountingMethodology: 'General Information'!$E$283
Name EmployeesReceivePayEqualOrAboveMinimumWageDeterminedByNationalLawOrCollectiveAgreement: 'Social Disclosures'!$D$147
Name EmployeeTurnoverRate: 'Social Disclosures'!$D$137
Name EnergyConsumptionFromElectricity_NonRenewableEnergyMember: 'Environmental Disclosures'!$J$12
Name EnergyConsumptionFromElectricity_RenewableEnergyMember: 'Environmental Disclosures'!$G$12
Name EnergyConsumptionFromElectricity_TotalRenewableAndNonRenewableEnergyMember: 'Environmental Disclosures'!$K$12
Name EnergyConsumptionFromFuels_NonRenewableEnergyMember: 'Environmental Disclosures'!$J$14
Name EnergyConsumptionFromFuels_RenewableEnergyMember: 'Environmental Disclosures'!$G$14
Name EnergyConsumptionFromFuels_TotalRenewableAndNonRenewableEnergyMember: 'Environmental Disclosures'!$K$14
Name EnergyConsumptionFromSelfGeneratedElectricity_NonRenewableEnergyMember: 'Environmental Disclosures'!$J$13
Name EnergyConsumptionFromSelfGeneratedElectricity_RenewableEnergyMember: 'Environmental Disclosures'!$G$13
Name EnergyConsumptionFromSelfGeneratedElectricity_TotalRenewableAndNonRenewableEnergyMember: 'Environmental Disclosures'!$K$13
Name enum_B2: 'Enumeration Lists'!$P$2:$P$4

Sheet Introduction
B1: =template_label_version | C1: 1.2.0
B2: =template_label_publication_date | C2: 46077
B3: {=IF(ISERROR(CELL("filename",A1)),"Warning: The Digital Template was developed and tested using Microsoft Excel 365. Functionality may be limited or incorrect when using other spreadsheet applications or older versions of Excel.","")}
B10: =template_label_taxonomy_entry_point | C10: https://xbrl.efrag.org/taxonomy/vsme/2026-02-01/vsme-all.xsd
B11: =template_label_select_template_display_language | C11: English - Official [en]
B12: =template_label_title_of_report | C12: =template_label_main_title_of_report_text
B13: =template_label_subtitle_of_report | C13: =template_label_subtitle_of_report_text
B14: =template_label_vsme_digital_template
B15: =template_label_the_purpose_of_this_digital_template_is_to_illustrate_how_vsme_reporting_can_be_implemented_in_a_digital_template
B18: =template_label_how_to_use_it
B19: =template_label_0_provide_information_that_is_mandatory_in_order_to_generate_the_vsme_and_xbrl_report
B20: =template_label_1_fill_in_the_disclosures_on_the_four_worksheets
B21: =template_label_2_find_more_information_on_the_actual_disclosure_requirements_in_the_vsme_standard
B22: =template_label_3_for_open_tables_like_the_list_of_subsidizers_sites_please_expand_the_groups_by_clicking_the_plus
B23: =template_label_4_validate_the_data_entered_by_checking_the_validation_status
B24: =template_label_5_convert_this_template_to_an_inline_xbrl_report
B25: =template_label_6_the_undertaking_may_also_upload_the_report_to_public_repositories_or_a_webpage
B27: =template_label_cell_background_color_index
B28: =template_label_general_principles | C28: =template_label_indicates_that_the_disclosure_is_from_the_general_principles_of_the_vsme
B29: =template_label_basic_module | C29: =template_label_indicates_that_the_disclosure_is_from_the_vsme_basic_module
B30: =template_label_comprehensive_module | C30: =template_label_indicates_that_the_disclosure_is_from_the_vsme_comprehensive_module
C31: =template_label_indicates_that_the_cell_is_automatically_calculated_and_that_no_data_entry_is_required
C32: =template_label_indicates_that_the_datapoint_often_a_condition_will_not_be_included_in_the_vsme_and_digital_xbrl_report
C33: =template_label_indicates_that_no_data_entry_is_required_unless_certain_logics_are_selected_in_the_disclosure_itself
B34: =template_label_validation_missing_value_error_velue_inconsistency_invalid_url | C34: =template_label_indicates_that_either_data_entry_is_incorrect_in_terms_of_format_or_that_certain_information
B35: Validation OK | C35: =template_label_indicates_that_data_entry_is_ok_and_the_undertaking_can_proceed_to_the_next_disclosure
B36: =template_label_validation_classified_or_sensitive_information | C36: =template_label_indicates_that_the_undertaking_has_omitted_the_data_entry_as_it_is_deemed_to_be_classified_or_sensitive_information
C37: =template_label_no_value_can_be_entered_in_the_cell
B38: [+] | C38: =template_label_lists_can_be_expanded_using_the_plus_button_on_the_left
B44: =template_label_efrag_is_funded_by_the_european_union_through_the_single_market_programme
B45: =template_label_reproduction_and_use_rights_are_strictly_limited

Sheet Table of Contents & Validation
B2: =template_label_table_of_contents_validation | C2: =template_label_overall_validation_status_validation | D2: =template_classified_or_sensitive_information
B3: =template_label_contents_grouping_follows_templates_framework | C3: {=IF(SUMPRODUCT(--((C5:C71<>template_label_ok)*(C5:C71<>"-")*(C5:C71<>"")*(C5:C71<>template_label_classified_or_sensitive_information))) > 0, template_label_incomplete, template_label_complete)} | D3: =template_filling_sensitive_checkboxes
C4: =template_label_specific_content_validation_status_validation
B5: =template_label_general_information_validation
B6: =template_label_information_on_the_report_necessary_for_xbrl_validation | C6: =IF( AND( COUNTIF('General Information'!F3:F12, template_label_missing_value) > 0, COUNTIF('General Information'!F3:F12, template_label_error) = 0 ), template_label_missing_value, IF( AND( COUNTIF('General Information'!F3:F12, template_label_error) > 0, COUNTIF('General Information'!F3:F12, template_label_missing_value) = 0 ), template_label_value_inconsistency, IF( AND( COUNTIF('General Information'!F3:F12, template_label_error) > 0, COUNTIF('General Information'!F3:F12, template_label_missing_value) > 0 ), template_label_error_plus_value_inconsistency, template_label_ok ) ) )
B7: =template_label_information_on_previous_reporting_period_validation | C7: =IF(COUNTIF('General Information'!F18:F119, template_label_missing_value) > 0, template_label_missing_value, IF(COUNTIF('General Information'!F18:F119, template_label_invalid_url ) > 0, template_label_invalid_url, IF(COUNTIF('General Information'!F18:F119, template_label_value_inconsistency ) > 0, template_label_value_inconsistency, IF(COUNTIF('General Information'!F18:F119, template_label_ok) > 0, template_label_ok, "-"))))
B8: =template_label_basic_module_validation
B9: =template_label_general_information_validation
B10: =template_label_b1_basis_for_preparation_validation | C10: =IF(D10=TRUE,template_label_classified_or_sensitive_information, IF(COUNTIF(C11:C15,template_label_error_plus_missing_value_plus_value_inconsistency)>0,template_label_error_plus_missing_value_plus_value_inconsistency, IF(COUNTIF(C11:C15,template_label_error_plus_value_inconsistency)>0,template_label_error_plus_value_inconsistency, IF(COUNTIF(C11:C15,template_label_error_plus_missing_value)>0,template_label_error_plus_missing_value, IF(COUNTIF(C11:C15,template_label_error)>0,template_label_error, IF(COUNTIF(C11:C15,template_label_missing_value_plus_value_inconsistency)>0,template_label_missing_value_plus_value_inconsistency, IF(COUNTIF(C11:C15,template_label_value_inconsistency)>0,template_label_value_inconsistency, IF(COUNTIF(C11:C15,template_label_missing_value)>0,template_label_missing_value, IF(COUNTIF(C11:C15,template_label_ok)=ROWS(C11:C15),template_label_ok, IF(COUNTIF(C11:C15,"-")=ROWS(C11:C15),"-", IF(AND(COUNTIF(C11:C15,template_label_ok)>0, COUNTIF(C11:C15,template_label_error_plus_missing_value_plus_value_inconsistency)=0, COUNTIF(C11:C15,template_label_error_plus_value_inconsistency)=0, COUNTIF(C11:C15,template_label_error_plus_missing_value)=0, COUNTIF(C11:C15,template_label_error)=0, COUNTIF(C11:C15,template_label_missing_value_plus_value_inconsistency)=0, COUNTIF(C11:C15,template_label_value_inconsistency)=0, COUNTIF(C11:C15,template_label_missing_value)=0, OR(COUNTIF(C11:C15,template_label_missing_value)=0, COUNTIF(C11:C15,template_label_missing_value)>0)), template_label_ok, "-"))))))))) )) | D10: =IF(COUNTIF(D12:D15,TRUE)=ROWS(D12:D15),TRUE,FALSE)
B11: =template_label_b1_basis_for_preparation | C11: =IF(COUNTIF('General Information'!F122,template_label_missing_value)>0,template_label_missing_value, IF(COUNTIF('General Information'!F122,template_label_ok)>0,template_label_ok,"-"))
B12: =template_label_b1_other_undertakings_general_information | C12: =IF(D12=TRUE, template_label_classified_or_sensitive_information,IF( AND( COUNTIF('General Information'!F177:F285,template_label_missing_value)>0, COUNTIF('General Information'!F177:F285,template_label_value_inconsistency)=0, COUNTIF('General Information'!F177:F285,template_label_error)=0 ), template_label_missing_value, IF( AND( COUNTIF('General Information'!F177:F285,template_label_value_inconsistency)>0, COUNTIF('General Information'!F177:F285,template_label_missing_value)=0, COUNTIF('General Information'!F177:F285,template_label_error)=0 ), template_label_value_inconsistency, IF( AND( COUNTIF('General Information'!F177:F285,template_label_value_inconsistency)=0, COUNTIF('General Information'!F177:F285,template_label_missing_value)=0, COUNTIF('General Information'!F177:F285,template_label_error)>0 ), template_label_error, IF( AND( COUNTIF('General Information'!F177:F285,template_label_value_inconsistency)>0, COUNTIF('General Information'!F177:F285,template_label_missing_value)>0, COUNTIF('General Information'!F177:F285,template_label_error)=0 ), template_label_missing_value_plus_value_inconsistency, IF( AND( COUNTIF('General Information'!F177:F285,template_label_value_inconsistency)=0, COUNTIF('General Information'!F177:F285,template_label_missing_value)>0, COUNTIF('General Information'!F177:F285,template_label_error)>0 ), template_label_error_plus_missing_value, IF( AND( COUNTIF('General Information'!F177:F285,template_label_value_inconsistency)>0, COUNTIF('General Information'!F177:F285,template_label_missing_value)=0, COUNTIF('General Information'!F177:F285,template_label_error)>0 ), template_label_error_plus_value_inconsistency, IF( AND( COUNTIF('General Information'!F177:F285,template_label_value_inconsistency)>0, COUNTIF('General Information'!F177:F285,template_label_missing_value)>0, COUNTIF('General Information'!F177:F285,template_label_error)>0 ), template_label_error_plus_missing_value_plus_value_inconsistency, IF( AND( COUNTIF('General Information'!F177:F285,template_label_value_inconsistency)=0, COUNTIF('General Information'!F177:F285,template_label_missing_value)=0, COUNTIF('General Information'!F177:F285,template_label_error)=0, COUNTIF('General Information'!F177:F285,template_label_ok)>0 ), template_label_ok, "-" ))))))))) | D12: FALSE
B13: =template_label_b1_list_of_subsidiaries | C13: =IF(D13=TRUE, template_label_classified_or_sensitive_information, IF( COUNTIF('General Information'!F290:F389, template_label_missing_value) > 0, template_label_missing_value, IF( COUNTIF('General Information'!F290:F389, template_label_ok) > 0, template_label_ok, "-" ) ) ) | D13: FALSE
B14: =template_label_b1_disclosure_of_sustainability_related_certification_or_label | C14: =IF(D14=TRUE, template_label_classified_or_sensitive_information, IF( COUNTIF('General Information'!I395, template_label_missing_value) > 0, template_label_missing_value, IF( COUNTIF('General Information'!I395, template_label_ok) > 0, template_label_ok, "-" ) ) ) | D14: FALSE
B15: =template_label_b1_list_of_site | C15: =IF(D15=TRUE, template_label_classified_or_sensitive_information, IF( COUNTIF('General Information'!I404:I503, template_label_missing_value) > 0, template_label_missing_value, IF( COUNTIF('General Information'!I404:I503, template_label_ok) > 0, template_label_ok, "-" ) ) ) | D15: FALSE
B16: =template_label_b2_practices_policies_and_future_initiatives_for_transitioning_towards_a_more_sustainable_economy_validation | C16: =IF(D16=TRUE,template_label_classified_or_sensitive_information, IF(COUNTIF(C17:C18,template_label_error_plus_missing_value_plus_value_inconsistency)>0,template_label_error_plus_missing_value_plus_value_inconsistency, IF(COUNTIF(C17:C18,template_label_error_plus_value_inconsistency)>0,template_label_error_plus_value_inconsistency, IF(COUNTIF(C17:C18,template_label_error_plus_missing_value)>0,template_label_error_plus_missing_value, IF(COUNTIF(C17:C18,template_label_error)>0,template_label_error, IF(COUNTIF(C17:C18,template_label_missing_value_plus_value_inconsistency)>0,template_label_missing_value_plus_value_inconsistency, IF(COUNTIF(C17:C18,template_label_value_inconsistency)>0,template_label_value_inconsistency, IF(COUNTIF(C17:C18,template_label_missing_value)>0,template_label_missing_value, IF(COUNTIF(C17:C18,template_label_ok)=ROWS(C17:C18),template_label_ok, IF(COUNTIF(C17:C18,"-")=ROWS(C17:C18),"-", IF(AND(COUNTIF(C17:C18,template_label_ok)>0, COUNTIF(C17:C18,template_label_error_plus_missing_value_plus_value_inconsistency)=0, COUNTIF(C17:C18,template_label_error_plus_value_inconsistency)=0, COUNTIF(C17:C18,template_label_error_plus_missing_value)=0, COUNTIF(C17:C18,template_label_error)=0, COUNTIF(C17:C18,template_label_missing_value_plus_value_inconsistency)=0, COUNTIF(C17:C18,template_label_value_inconsistency)=0, COUNTIF(C17:C18,template_label_missing_value)=0,OR(COUNTIF(C17:C18,template_label_missing_value)=0, COUNTIF(C17:C18,template_label_missing_value)>0)), template_label_ok, "-"))))))))) )) | D16: =IF(COUNTIF(D17:D18,TRUE)=ROWS(D17:D18),TRUE,FALSE)
B17: =template_label_b2_practices_policies_and_future_initiatives_for_transitioning_towards_a_more_sustainable_economy | C17: =IF(D17=TRUE, template_label_classified_or_sensitive_information, IF( COUNTIF('General Information'!P510, template_label_missing_value) > 0, template_label_missing_value, IF( COUNTIF('General Information'!P510, template_label_ok) > 0, template_label_ok, "-" ) ) ) | D17: FALSE
B18: =template_label_b2_cooperative_specific_disclosures | C18: {=IF(D18=TRUE, template_label_classified_or_sensitive_information, IF(OR('General Information'!E514:E516=template_label_ok),template_label_ok,"-") )} | D18: FALSE
B19: =template_label_environmental_disclosures_validation
B20: =template_label_b3_energy_and_greenhouse_gas_emissions_validation | C20: =IF(D20=TRUE,template_label_classified_or_sensitive_information, IF(COUNTIF(C21:C24,template_label_error_plus_missing_value_plus_value_inconsistency)>0,template_label_error_plus_missing_value_plus_value_inconsistency, IF(COUNTIF(C21:C24,template_label_error_plus_value_inconsistency)>0,template_label_error_plus_value_inconsistency, IF(COUNTIF(C21:C24,template_label_error_plus_missing_value)>0,template_label_error_plus_missing_value, IF(COUNTIF(C21:C24,template_label_error)>0,template_label_error, IF(COUNTIF(C21:C24,template_label_missing_value_plus_value_inconsistency)>0,template_label_missing_value_plus_value_inconsistency, IF(COUNTIF(C21:C24,template_label_value_inconsistency)>0,template_label_value_inconsistency, IF(COUNTIF(C21:C24,template_label_missing_value)>0,template_label_missing_value, IF(COUNTIF(C21:C24,template_label_ok)=ROWS(C21:C24),template_label_ok, IF(COUNTIF(C21:C24,"-")=ROWS(C21:C24),"-", IF(AND(COUNTIF(C21:C24,template_label_ok)>0, COUNTIF(C21:C24,template_label_error_plus_missing_value_plus_value_inconsistency)=0, COUNTIF(C21:C24,template_label_error_plus_value_inconsistency)=0, COUNTIF(C21:C24,template_label_error_plus_missing_value)=0, COUNTIF(C21:C24,template_label_error)=0, COUNTIF(C21:C24,template_label_missing_value_plus_value_inconsistency)=0, COUNTIF(C21:C24,template_label_value_inconsistency)=0, COUNTIF(C21:C24,template_label_missing_value)=0,OR(COUNTIF(C21:C24,template_label_missing_value)=0, COUNTIF(C21:C24,template_label_missing_value)>0)), template_label_ok, "-"))))))))) )) | D20: =IF(COUNTIF(D21:D24,TRUE)=ROWS(D21:D24),TRUE,FALSE)
B21: =template_label_b3_total_energy_consumption | C21: =IF(D21=TRUE, template_label_classified_or_sensitive_information, IF(COUNTIF('Environmental Disclosures'!L5,template_label_missing_value)>0,template_label_missing_value, IF(COUNTIF('Environmental Disclosures'!L5,template_label_ok)>0,template_label_ok,"-")) ) | D21: FALSE
B22: =template_label_b3_breakdown_of_energy_consumption | C22: =IF(D22=TRUE,template_label_classified_or_sensitive_information, IF( AND( COUNTIF('Environmental Disclosures'!L12:L14,template_label_missing_value)>0, COUNTIF('Environmental Disclosures'!L12:L14,template_label_value_inconsistency)=0 ), template_label_missing_value, IF( AND( COUNTIF('Environmental Disclosures'!L12:L14,template_label_value_inconsistency)>0, COUNTIF('Environmental Disclosures'!L12:L14,template_label_missing_value)=0 ), template_label_value_inconsistency, IF( AND( COUNTIF('Environmental Disclosures'!L12:L14,template_label_value_inconsistency)>0, COUNTIF('Environmental Disclosures'!L12:L14,template_label_missing_value)>0 ), template_label_error_plus_value_inconsistency, IF( COUNTIF('Environmental Disclosures'!L12:L14,"-")=3, "-", IF( COUNTIF('Environmental Disclosures'!L12:L14,template_label_ok)>0, template_label_ok, "-" ) )) )) ) | D22: FALSE
B23: =template_label_b3_estimated_greenhouse_gas_emissions | C23: =IF(D23=TRUE, template_label_classified_or_sensitive_information, IF(COUNTIF('Environmental Disclosures'!L21:L44,template_label_missing_value)>0,template_label_missing_value, IF(COUNTIF('Environmental Disclosures'!L21:L44,template_label_ok)>0,template_label_ok,"-")) ) | D23: FALSE
B24: =template_label_b3_greenhouse_gas_emission_intensity_per_turnover | C24: =IF(D24=TRUE, template_label_classified_or_sensitive_information, IF(C23=template_label_ok,template_label_ok,"-") ) | D24: FALSE
B25: =template_label_b4_pollution_of_air_water_and_soil_validation | C25: =IF(D25=TRUE, template_label_classified_or_sensitive_information, IF(COUNTIF('Environmental Disclosures'!L75:L179,template_label_invalid_url)>0, template_label_invalid_url, IF(AND(COUNTIF('Environmental Disclosures'!L75:L179,template_label_missing_value)>0, COUNTIF('Environmental Disclosures'!L75:L179,template_label_value_inconsistency)>0), template_label_missing_value_plus_value_inconsistency, IF(COUNTIF('Environmental Disclosures'!L75:L179,template_label_missing_value)>0, template_label_missing_value, IF(COUNTIF('Environmental Disclosures'!L75:L179,template_label_value_inconsistency)>0, template_label_value_inconsistency, IF(COUNTIF('Environmental Disclosures'!L75:L179,template_label_ok)>0, template_label_ok, "-"))))) ) | D25: FALSE
B26: =template_label_b5_biodiversity_validation | C26: =IF(D26=TRUE, template_label_classified_or_sensitive_information, IF(COUNTIF(C27:C28,template_label_error_plus_missing_value_plus_value_inconsistency)>0,template_label_error_plus_missing_value_plus_value_inconsistency, IF(COUNTIF(C27:C28,template_label_error_plus_value_inconsistency)>0,template_label_error_plus_value_inconsistency, IF(COUNTIF(C27:C28,template_label_error_plus_missing_value)>0,template_label_error_plus_missing_value, IF(COUNTIF(C27:C28,template_label_error)>0,template_label_error, IF(COUNTIF(C27:C28,template_label_missing_value_plus_value_inconsistency)>0,template_label_missing_value_plus_value_inconsistency, IF(COUNTIF(C27:C28,template_label_value_inconsistency)>0,template_label_value_inconsistency, IF(COUNTIF(C27:C28,template_label_missing_value)>0,template_label_missing_value, IF(COUNTIF(C27:C28,template_label_ok)=ROWS(C27:C28),template_label_ok, IF(COUNTIF(C27:C28,"-")=ROWS(C27:C28),"-", IF(AND(COUNTIF(C27:C28,template_label_ok)>0, COUNTIF(C27:C28,template_label_error_plus_missing_value_plus_value_inconsistency)=0, COUNTIF(C27:C28,template_label_error_plus_value_inconsistency)=0, COUNTIF(C27:C28,template_label_error_plus_missing_value)=0, COUNTIF(C27:C28,template_label_error)=0, COUNTIF(C27:C28,template_label_missing_value_plus_value_inconsistency)=0, COUNTIF(C27:C28,template_label_value_inconsistency)=0, COUNTIF(C27:C28,template_label_missing_value)=0,OR(COUNTIF(C27:C28,template_label_missing_value)=0, COUNTIF(C27:C28,template_label_missing_value)>0)), template_label_ok, "-"))))))))) )) | D26: =IF(COUNTIF(D27:D28,TRUE)=ROWS(D27:D28),TRUE,FALSE)
B27: =template_label_b5_sites_in_biodiversity_sensitive_areas | C27: =IF(D27=TRUE, template_label_classified_or_sensitive_information, IF(AND( COUNTIF('Environmental Disclosures'!D188:D287,template_label_ok) + COUNTIF('Environmental Disclosures'!L186:L287,template_label_ok) > 0, COUNTIF('Environmental Disclosures'!D188:D287,template_label_missing_value) + COUNTIF('Environmental Disclosures'!L186:L287,template_label_missing_value) = 0, COUNTIF('Environmental Disclosures'!D188:D287,template_label_value_inconsistency) + COUNTIF('Environmental Disclosures'!L186:L287,template_label_value_inconsistency) = 0), template_label_ok, IF(AND( COUNTIF('Environmental Disclosures'!D188:D287,template_label_missing_value) + COUNTIF('Environmental Disclosures'!L186:L287,template_label_missing_value) > 0, COUNTIF('Environmental Disclosures'!D188:D287,template_label_value_inconsistency) + COUNTIF('Environmental Disclosures'!L186:L287,template_label_value_inconsistency) = 0), template_label_missing_value, IF(AND( COUNTIF('Environmental Disclosures'!D188:D287,template_label_value_inconsistency) + COUNTIF('Environmental Disclosures'!L186:L287,template_label_value_inconsistency) > 0, COUNTIF('Environmental Disclosures'!D188:D287,template_label_missing_value) + COUNTIF('Environmental Disclosures'!L186:L287,template_label_missing_value) = 0), template_label_value_inconsistency, IF(AND( COUNTIF('Environmental Disclosures'!D188:D287,template_label_value_inconsistency) + COUNTIF('Environmental Disclosures'!L186:L287,template_label_value_inconsistency) > 0, COUNTIF('Environmental Disclosures'!D188:D287,template_label_missing_value) + COUNTIF('Environmental Disclosures'!L186:L287,template_label_missing_value) > 0), template_label_missing_value_plus_value_inconsistency, "-" ) ) ) ) ) | D27: FALSE
B28: =template_label_b5_biodiversity_land_use | C28: =IF(D28=TRUE, template_label_classified_or_sensitive_information, IF( AND( COUNTIF('Environmental Disclosures'!G293:G298,template_label_missing_value)>0, COUNTIF('Environmental Disclosures'!G293:G298,template_label_value_inconsistency)=0, COUNTIF('Environmental Disclosures'!G293:G298,template_label_ok)>=0 ), template_label_missing_value, IF( AND( COUNTIF('Environmental Disclosures'!G293:G298,template_label_value_inconsistency)>0, COUNTIF('Environmental Disclosures'!G293:G298,template_label_missing_value)=0, COUNTIF('Environmental Disclosures'!G293:G298,template_label_ok)>=0 ), template_label_value_inconsistency, IF( AND( COUNTIF('Environmental Disclosures'!G293:G298,template_label_value_inconsistency)>0, COUNTIF('Environmental Disclosures'!G293:G298,template_label_missing_value)>0, COUNTIF('Environmental Disclosures'!G293:G298,template_label_ok)>=0 ), template_label_missing_value_plus_value_inconsistency, IF( AND( COUNTIF('Environmental Disclosures'!G293:G298,template_label_value_inconsistency)=0, COUNTIF('Environmental Disclosures'!G293:G298,template_label_missing_value)=0, COUNTIF('Environmental Disclosures'!G293:G298,template_label_ok)>0 ), template_label_ok, "-" ) ) )) ) | D28: FALSE
B29: =template_label_b6_water_validation | C29: =IF(D29=TRUE, template_label_classified_or_sensitive_information, IF(COUNTIF(C30:C31,template_label_error_plus_missing_value_plus_value_inconsistency)>0,template_label_error_plus_missing_value_plus_value_inconsistency, IF(COUNTIF(C30:C31,template_label_error_plus_value_inconsistency)>0,template_label_error_plus_value_inconsistency, IF(COUNTIF(C30:C31,template_label_error_plus_missing_value)>0,template_label_error_plus_missing_value, IF(COUNTIF(C30:C31,template_label_error)>0,template_label_error, IF(COUNTIF(C30:C31,template_label_missing_value_plus_value_inconsistency)>0,template_label_missing_value_plus_value_inconsistency, IF(COUNTIF(C30:C31,template_label_value_inconsistency)>0,template_label_value_inconsistency, IF(COUNTIF(C30:C31,template_label_missing_value)>0,template_label_missing_value, IF(COUNTIF(C30:C31,template_label_ok)=ROWS(C30:C31),template_label_ok, IF(COUNTIF(C30:C31,"-")=ROWS(C30:C31),"-", IF(AND(COUNTIF(C30:C31,template_label_ok)>0, COUNTIF(C27:C28,template_label_error_plus_missing_value_plus_value_inconsistency)=0, COUNTIF(C30:C31,template_label_error_plus_value_inconsistency)=0, COUNTIF(C30:C31,template_label_error_plus_missing_value)=0, COUNTIF(C30:C31,template_label_error)=0, COUNTIF(C30:C31,template_label_missing_value_plus_value_inconsistency)=0, COUNTIF(C30:C31,template_label_value_inconsistency)=0, COUNTIF(C30:C31,template_label_missing_value)=0,OR(COUNTIF(C30:C31,template_label_missing_value)=0, COUNTIF(C30:C31,template_label_missing_value)>0)), template_label_ok, "-"))))))))) )) | D29: =IF(COUNTIF(D30:D31,TRUE)=ROWS(D30:D31),TRUE,FALSE)
B30: =template_label_b6_water_withdrawal | C30: =IF(D30=TRUE, template_label_classified_or_sensitive_information, IF(COUNTIF('Environmental Disclosures'!E303:F304, template_label_missing_value) > 0, template_label_missing_value, IF(COUNTIF('Environmental Disclosures'!E303:F304, template_label_ok) > 0, template_label_ok, "-")) ) | D30: FALSE
B31: =template_label_b6_water_consumption | C31: =IF(D31=TRUE, template_label_classified_or_sensitive_information, IF(COUNTIF('Environmental Disclosures'!E310:F310, template_label_missing_value) > 0, template_label_missing_value, IF(COUNTIF('Environmental Disclosures'!E310:F310, template_label_ok) > 0, template_label_ok, "-")) ) | D31: FALSE
B32: =template_label_b7_resource_use_circular_economy_and_waste_management_validation | C32: =IF(D32=TRUE, template_label_classified_or_sensitive_information, IF(COUNTIF(C33:C35, template_label_error_plus_missing_value_plus_value_inconsistency) > 0, template_label_error_plus_missing_value_plus_value_inconsistency, IF(COUNTIF(C33:C35, template_label_error_plus_value_inconsistency) > 0, template_label_error_plus_value_inconsistency, IF(COUNTIF(C33:C35, template_label_error_plus_missing_value) > 0, template_label_error_plus_missing_value, IF(COUNTIF(C33:C35, template_label_error) > 0, template_label_error, IF(COUNTIF(C33:C35, template_label_missing_value_plus_value_inconsistency) > 0, template_label_missing_value_plus_value_inconsistency, IF(COUNTIF(C33:C35, template_label_value_inconsistency) > 0, template_label_value_inconsistency, IF(COUNTIF(C33:C35, template_label_missing_value) > 0, template_label_missing_value, IF(COUNTIF(C33:C35, template_label_ok) = ROWS(C33:C35), template_label_ok, IF(COUNTIF(C33:C35, "-") = ROWS(C33:C35), "-", IF(AND(COUNTIF(C33:C35,template_label_ok)>0, COUNTIF(C33:C35,template_label_error_plus_missing_value_plus_value_inconsistency)=0, COUNTIF(C33:C35,template_label_error_plus_value_inconsistency)=0, COUNTIF(C33:C35,template_label_error_plus_missing_value)=0, COUNTIF(C33:C35,template_label_error)=0, COUNTIF(C33:C35,template_label_missing_value_plus_value_inconsistency)=0, COUNTIF(C33:C35,template_label_value_inconsistency)=0, COUNTIF(C33:C35,template_label_missing_value)=0,OR(COUNTIF(C33:C35,template_label_missing_value)=0, COUNTIF(C33:C35,template_label_missing_value)>0)), template_label_ok, "-"))))))))) )) | D32: =IF(COUNTIF(D34:D35,TRUE)=ROWS(D34:D35),TRUE,FALSE)
B33: =template_label_b7_description_of_circular_economy_principles | C33: =IF(D33=TRUE, template_label_classified_or_sensitive_information, IF( AND( COUNTIF('Environmental Disclosures'!H316:I317, template_label_missing_value) > 0, COUNTIF('Environmental Disclosures'!H316:I317, template_label_value_inconsistency) = 0, COUNTIF('Environmental Disclosures'!H316:I317, template_label_ok) >= 0 ), template_label_missing_value, IF( AND( COUNTIF('Environmental Disclosures'!H316:I317, template_label_value_inconsistency) > 0, COUNTIF('Environmental Disclosures'!H316:I317, template_label_missing_value) = 0, COUNTIF('Environmental Disclosures'!H316:I317, template_label_ok) >= 0 ), template_label_value_inconsistency, IF( AND( COUNTIF('Environmental Disclosures'!H316:I317, template_label_value_inconsistency) > 0, COUNTIF('Environmental Disclosures'!H316:I317, template_label_missing_value) > 0, COUNTIF('Environmental Disclosures'!H316:I317, template_label_ok) >= 0 ), template_label_missing_value_plus_value_inconsistency, IF( AND( COUNTIF('Environmental Disclosures'!H316:I317, template_label_value_inconsistency) = 0, COUNTIF('Environmental Disclosures'!H316:I317, template_label_missing_value) = 0, COUNTIF('Environmental Disclosures'!H316:I317, template_label_ok) > 0 ), template_label_ok, "-" ) ) )) ) | D33: FALSE
B34: =template_label_b7_waste_generated | C34: =IF(D34=TRUE, template_label_classified_or_sensitive_information, IF( AND( COUNTIF('Environmental Disclosures'!M323:M423, template_label_error) > 0, COUNTIF('Environmental Disclosures'!M323:M423, template_label_missing_value) > 0, COUNTIF('Environmental Disclosures'!M323:M423, template_label_value_inconsistency) > 0 ), template_label_error_plus_missing_value_plus_value_inconsistency, IF( AND( COUNTIF('Environmental Disclosures'!M323:M423, template_label_error) > 0, COUNTIF('Environmental Disclosures'!M323:M423, template_label_value_inconsistency) > 0, COUNTIF('Environmental Disclosures'!M323:M423, template_label_missing_value) = 0 ), template_label_error_plus_value_inconsistency, IF( AND( COUNTIF('Environmental Disclosures'!M323:M423, template_label_error) > 0, COUNTIF('Environmental Disclosures'!M323:M423, template_label_missing_value) > 0, COUNTIF('Environmental Disclosures'!M323:M423, template_label_value_inconsistency) = 0 ), template_label_error_plus_missing_value, IF( AND( COUNTIF('Environmental Disclosures'!M323:M423, template_label_missing_value) > 0, COUNTIF('Environmental Disclosures'!M323:M423, template_label_value_inconsistency) > 0, COUNTIF('Environmental Disclosures'!M323:M423, template_label_error) = 0 ), template_label_missing_value_plus_value_inconsistency, IF( AND( COUNTIF('Environmental Disclosures'!M323:M423, template_label_error) > 0, COUNTIF('Environmental Disclosures'!M323:M423, template_label_missing_value) = 0, COUNTIF('Environmental Disclosures'!M323:M423, template_label_value_inconsistency) = 0 ), template_label_error, IF( AND( COUNTIF('Environmental Disclosures'!M323:M423, template_label_missing_value) > 0, COUNTIF('Environmental Disclosures'!M323:M423, template_label_error) = 0, COUNTIF('Environmental Disclosures'!M323:M423, template_label_value_inconsistency) = 0 ), template_label_missing_value, IF( AND( COUNTIF('Environmental Disclosures'!M323:M423, template_label_value_inconsistency) > 0, COUNTIF('Environmental Disclosures'!M323:M423, template_label_error) = 0, COUNTIF('Environmental Disclosures'!M323:M423, template_label_missing_value) = 0 ), template_label_value_inconsistency, IF( AND( COUNTIF('Environmental Disclosures'!M323:M423, template_label_error) = 0, COUNTIF('Environmental Disclosures'!M323:M423, template_label_missing_value) = 0, COUNTIF('Environmental Disclosures'!M323:M423, template_label_value_inconsistency) = 0, COUNTIF('Environmental Disclosures'!M323:M423, template_label_ok) > 0 ), template_label_ok, "-" )))))))) ) | D34: FALSE
B35: =template_label_b7_annual_mass_flow_of_relevant_materials_used | C35: =IF(D35=TRUE, template_label_classified_or_sensitive_information, IF(COUNTIF('Environmental Disclosures'!K435:K534, template_label_missing_value) > 0, template_label_missing_value, IF(COUNTIF('Environmental Disclosures'!K435:K534, template_label_ok) > 0, template_label_ok, "-")) ) | D35: FALSE
B36: =template_label_social_disclosures_validation
B37: =template_label_b8_workforce_general_characteristics_validation | C37: =IF(D37=TRUE, template_label_classified_or_sensitive_information, IF(COUNTIF(C38:C41, template_label_error_plus_missing_value_plus_value_inconsistency) > 0, template_label_error_plus_missing_value_plus_value_inconsistency, IF(COUNTIF(C38:C41, template_label_error_plus_value_inconsistency) > 0, template_label_error_plus_value_inconsistency, IF(COUNTIF(C38:C41, template_label_error_plus_missing_value) > 0, template_label_error_plus_missing_value, IF(COUNTIF(C38:C41, template_label_error) > 0, template_label_error, IF(COUNTIF(C38:C41, template_label_missing_value_plus_value_inconsistency) > 0, template_label_missing_value_plus_value_inconsistency, IF(COUNTIF(C38:C41, template_label_value_inconsistency) > 0, template_label_value_inconsistency, IF(COUNTIF(C38:C41, template_label_missing_value) > 0, template_label_missing_value, IF(COUNTIF(C38:C41, template_label_ok) = ROWS(C38:C41), template_label_ok, IF(COUNTIF(C38:C41, "-") = ROWS(C38:C41), "-", IF(AND(COUNTIF(C38:C41,template_label_ok)>0, COUNTIF(C38:C41,template_label_error_plus_missing_value_plus_value_inconsistency)=0, COUNTIF(C38:C41,template_label_error_plus_value_inconsistency)=0, COUNTIF(C38:C41,template_label_error_plus_missing_value)=0, COUNTIF(C38:C41,template_label_error)=0, COUNTIF(C38:C41,template_label_missing_value_plus_value_inconsistency)=0, COUNTIF(C38:C41,template_label_value_inconsistency)=0, COUNTIF(C38:C41,template_label_missing_value)=0,OR(COUNTIF(C38:C41,template_label_missing_value)=0, COUNTIF(C38:C41,template_label_missing_value)>0)), template_label_ok, "-"))))))))) )) | D37: =IF(COUNTIF(D38:D41,TRUE)=ROWS(D38:D41),TRUE,FALSE)
B38: =template_label_b8_workforce_general_characteristics_type_of_contract | C38: =IF(D38=TRUE, template_label_classified_or_sensitive_information, IF(COUNTIF('Social Disclosures'!H10, template_label_missing_value) > 0, template_label_missing_value, IF(COUNTIF('Social Disclosures'!H10, template_label_ok) > 0, template_label_ok, "-")) ) | D38: FALSE
B39: =template_label_b8_workforce_general_characteristics_gender | C39: =IF(D39=TRUE,template_label_classified_or_sensitive_information, IF(COUNTIF('Social Disclosures'!H18,template_label_missing_value)>0, template_label_missing_value,IF(COUNTIF('Social Disclosures'!H18,template_label_value_inconsistency)>0, template_label_value_inconsistency, IF(COUNTIF('Social Disclosures'!H18,template_label_ok)>0, template_label_ok, "-")) )) | D39: FALSE
B40: =template_label_b8_workforce_general_characteristics_country_of_employment | C40: =IF(D40=TRUE, template_label_classified_or_sensitive_information, IF(COUNTIF('Social Disclosures'!I29:I128, template_label_missing_value) > 0, template_label_missing_value, IF(COUNTIF('Social Disclosures'!I29:I128, template_label_ok) > 0, template_label_ok, "-")) ) | D40: FALSE
B41: =template_label_b8_workforce_general_characteristics_turnover_rate | C41: =IF(D41=TRUE, template_label_classified_or_sensitive_information, IF(COUNTIF('Social Disclosures'!I134:I136, template_label_missing_value) > 0, template_label_missing_value, IF(COUNTIF('Social Disclosures'!I134:I136, template_label_ok) > 0, template_label_ok, "-")) ) | D41: FALSE
...

Sheet General Information
A1: =template_label_paragraph_reference | B1: =template_label_paragraph_guidance_reference
C2: =template_label_information_on_the_report_necessary_for_xbrl & " " & template_label_always_to_be_reported
C3: =template_label_name_of_the_reporting_entity | D3: Company XYZ | F3: =IF(D3 = "", template_label_missing_value, template_label_ok)
C4: =template_label_identifier_of_the_reporting_entity | D4: LEI | E4: TestCode1234 | F4: =IF(OR(D4 = "", E4 = ""), template_label_missing_value, template_label_ok) | G4: =template_label_identifier_warning
C5: =template_label_currency_of_the_monetary_values_in_the_report | D5: EUR | F5: =IF(D5 = "", template_label_missing_value, template_label_ok)
C6: =template_label_starting_year | D6: 2024 | F6: =IF(OR(D6 = "", D7 = "", D8 = ""), template_label_missing_value, IF(OR( AND(D7 = 2, D8 > 29), AND(D7 = 2, D8 = 29, NOT(AND(MOD(D6, 4) = 0, OR(MOD(D6, 100) <> 0, MOD(D6, 400) = 0)))), AND(OR(D7 = 4, D7 = 6, D7 = 9, D7 = 11), D8 = 31) ), template_label_error, IF(F10 = template_label_value_inconsistency, template_label_value_inconsistency, template_label_ok) ) ) | G6: =template_label_date_warning
C7: =template_label_starting_month | D7: 1
C8: =template_label_starting_day | D8: 1
C9: =template_label_reporting_period_start_date | D9: =IF(OR(ISBLANK(D6), ISBLANK(D7), ISBLANK(D8)), "-", D6 & "-" & TEXT(D7, "00") & "-" & TEXT(D8, "00"))
C10: =template_label_ending_year | D10: 2024 | F10: =IF(OR(D10 = "", D11 = "", D12 = ""), template_label_missing_value, IF(OR( AND(D11 = 2, D12 > 29), AND(D11 = 2, D12 = 29, NOT(AND(MOD(D10, 4) = 0, OR(MOD(D10, 100) <> 0, MOD(D10, 400) = 0)))), AND(OR(D11 = 4, D11 = 6, D11 = 9, D11 = 11), D12 = 31) ), template_label_error, IF(D10 < D6, template_label_value_inconsistency, IF(D10 > D6, template_label_ok, IF(AND(D10 = D6, MATCH(D11, {1;2;3;4;5;6;7;8;9;10;11;12}, 0) < MATCH(D7, {1;2;3;4;5;6;7;8;9;10;11;12}, 0)), template_label_value_inconsistency, IF(AND(D10 = D6, MATCH(D11, {1;2;3;4;5;6;7;8;9;10;11;12}, 0) > MATCH(D7, {1;2;3;4;5;6;7;8;9;10;11;12}, 0)), template_label_ok, IF(AND(D10 = D6, MATCH(D11, {1;2;3;4;5;6;7;8;9;10;11;12}, 0) = MATCH(D7, {1;2;3;4;5;6;7;8;9;10;11;12}, 0), D12 < D8), template_label_value_inconsistency, template_label_ok ))))))) | G10: =template_label_date_warning
C11: =template_label_ending_month | D11: 12
C12: Ending day | D12: 31
C13: =template_label_reporting_period_end_date | D13: =IF(OR(ISBLANK(D10), ISBLANK(D11), ISBLANK(D12)), "-", D10 & "-" & TEXT(D11, "00") & "-" & TEXT(D12, "00"))
C16: =template_label_information_on_previous_reporting_period
C17: 16
C18: =template_label_disclosures_from_the_previous_reporting_period_that_remain_unchanged | E18: TRUE | F18: =IF(E18 = FALSE, "", template_label_ok)
C19: =template_label_disclosures_for_which_no_changes_are_reported_compared_to_the_previous_period_reporting | E19: B2 – Practices, policies and future initiatives for transitioning towards a more sustainable economy | F19: =IF(AND(E18 = FALSE, E19 = ""), "", IF(AND(E18 = FALSE, E19 <> ""), "", IF(AND(E18 = TRUE, E19 = ""), template_label_missing_value, IF(AND(E18 = TRUE, E19 <> "", COUNTIF(E19:E118, E19) = COUNTA(E19:E118), COUNTA(E19:E118) > 1), template_label_value_inconsistency, template_label_ok)))) | G19: =template_label_additional_rows_warning
E20: B3 – Energy and greenhouse gas emissions | F20: =IF($E$18 = FALSE, "", IF(E20 = "", "", IF(COUNTIF($E$19:$E$118, E20) > 1, template_label_value_inconsistency, template_label_ok)))
F21: =IF($E$18 = FALSE, "", IF(E21 = "", "", IF(COUNTIF($E$19:$E$118, E21) > 1, template_label_value_inconsistency, template_label_ok)))
F22: =IF($E$18 = FALSE, "", IF(E22 = "", "", IF(COUNTIF($E$19:$E$118, E22) > 1, template_label_value_inconsistency, template_label_ok)))
F23: =IF($E$18 = FALSE, "", IF(E23 = "", "", IF(COUNTIF($E$19:$E$118, E23) > 1, template_label_value_inconsistency, template_label_ok)))
F24: =IF($E$18 = FALSE, "", IF(E24 = "", "", IF(COUNTIF($E$19:$E$118, E24) > 1, template_label_value_inconsistency, template_label_ok)))
F25: =IF($E$18 = FALSE, "", IF(E25 = "", "", IF(COUNTIF($E$19:$E$118, E25) > 1, template_label_value_inconsistency, template_label_ok)))
F26: =IF($E$18 = FALSE, "", IF(E26 = "", "", IF(COUNTIF($E$19:$E$118, E26) > 1, template_label_value_inconsistency, template_label_ok)))
F27: =IF($E$18 = FALSE, "", IF(E27 = "", "", IF(COUNTIF($E$19:$E$118, E27) > 1, template_label_value_inconsistency, template_label_ok)))
C119: =template_label_link_to_previous_report_containing_disclosures_that_remain_unchanged | E119: www.Test.Report.com | F119: =IF(AND(E18 = FALSE, E119 = ""), "", IF(AND(E18 = TRUE, E119 = ""), template_label_missing_value, IF(AND(E18 = FALSE, E119 <> ""), "", IF(AND(E18 = TRUE, E119 <> "", OR(LEFT(E119, 7) = "http://", LEFT(E119, 8) = "https://", LEFT(E119, 4) = "www.")), template_label_ok, IF(E18 = TRUE, template_label_invalid_url, template_label_missing_value)))))
C121: =template_label_b1_basis_for_preparation & " " & template_label_from & " " & template_starting_date_display & " " & template_label_to & " " & template_ending_date_display & " " & template_label_always_to_be_reported
A122: 24(a) | B122: N/A | C122: =template_label_basis_for_preparation | E122: Option B (Basic Module and Comprehensive Module) | F122: =IF( 'Table of Contents & Validation'!D11=TRUE, IF(E122 = "", "", template_label_ok), IF(E122 = "", template_label_missing_value, template_label_ok) )
A123: 24(b) | B123: N/A | C123: =template_label_list_of_omitted_disclosures_deemed_to_be_classified_or_sensitive_information | E123: =_xlfn.XLOOKUP('Technical Sheet'!A28, 'Technical Sheet'!E106:E167, 'Table of Contents & Validation'!B10:B71, "") | F123: =template_label_bold_omitted_information
E124: =_xlfn.XLOOKUP('Technical Sheet'!A29, 'Technical Sheet'!E107:E168, 'Table of Contents & Validation'!B11:B72, "")
E125: =_xlfn.XLOOKUP('Technical Sheet'!A30, 'Technical Sheet'!E108:E169, 'Table of Contents & Validation'!B12:B73, "")
E126: =_xlfn.XLOOKUP('Technical Sheet'!A31, 'Technical Sheet'!E109:E170, 'Table of Contents & Validation'!B13:B74, "")
E127: =_xlfn.XLOOKUP('Technical Sheet'!A32, 'Technical Sheet'!E110:E171, 'Table of Contents & Validation'!B14:B75, "")
E128: =_xlfn.XLOOKUP('Technical Sheet'!A33, 'Technical Sheet'!E111:E172, 'Table of Contents & Validation'!B15:B76, "")
E129: =_xlfn.XLOOKUP('Technical Sheet'!A34, 'Technical Sheet'!E112:E173, 'Table of Contents & Validation'!B16:B77, "")
E130: =_xlfn.XLOOKUP('Technical Sheet'!A35, 'Technical Sheet'!E113:E174, 'Table of Contents & Validation'!B17:B78, "")
E131: =_xlfn.XLOOKUP('Technical Sheet'!A36, 'Technical Sheet'!E114:E175, 'Table of Contents & Validation'!B18:B79, "")
E132: =_xlfn.XLOOKUP('Technical Sheet'!A37, 'Technical Sheet'!E115:E176, 'Table of Contents & Validation'!B19:B80, "")
E133: =_xlfn.XLOOKUP('Technical Sheet'!A38, 'Technical Sheet'!E116:E177, 'Table of Contents & Validation'!B20:B81, "")
E134: =_xlfn.XLOOKUP('Technical Sheet'!A39, 'Technical Sheet'!E117:E178, 'Table of Contents & Validation'!B21:B82, "")
...

Sheet Environmental Disclosures
A1: =template_label_paragraph_reference | B1: =template_label_paragraph_guidance_reference
C2: =template_label_b3_total_energy_consumption&" "&template_label_from&" "&template_starting_date_display&" "&template_label_to&" "&template_ending_date_display&" "&template_label_always_to_be_reported
C3: 29
C4: 18-25
C5: =template_label_total_energy_consumption | G5: 250 | L5: =IF(OR( 'Table of Contents & Validation'!D21=TRUE, 'Table of Contents & Validation'!D20=TRUE), IF(AND(OR('General Information'!E122="Option A (Basic Module only)", 'General Information'!E122="Option B (Basic Module and Comprehensive Module)"), G5=""), "", IF('General Information'!E122="", "", template_label_ok)), IF(AND(OR('General Information'!E122="Option A (Basic Module only)", 'General Information'!E122="Option B (Basic Module and Comprehensive Module)"), G5=""), template_label_missing_value, IF('General Information'!E122="", "", template_label_ok)) )
C7: =template_label_b3_breakdown_of_energy_consumption&" "&template_label_from&" "&template_starting_date_display&" "&template_label_to&" "&template_ending_date_display&" "&template_label_if_applicable
C8: 29
C9: 18-25
C10: =template_label_has_the_undertaking_obtained_the_necessary_information_to_provide_an_energy_consumption_breakdown | G10: TRUE
G11: =template_label_renewable | J11: =template_label_non_renewable | K11: =template_label_total_renewable_and_nonrenewable
C12: =template_label_electricity | G12: 10 | J12: 100 | L12: {=IF(G10=TRUE, IF(SUMPRODUCT(--(G12:J14<>"-"), --(G12:J14<>""))>0, IF(SUM(G12:J14) > TotalEnergyConsumption, template_label_value_inconsistency, template_label_ok), template_label_missing_value), "")}
C13: =template_label_selfgenerated_electricity | G13: 23 | J13: 20
C14: =template_label_fuels | M14: =template_label_energy_consumption_warning
C16: =template_label_b3_estimated_greenhouse_gas_emissions& " "&template_label_always_to_be_reported | G16: =template_label_c3_ghg_reduction_targets&" "&template_label_if_applicable
C17: 30 | G17: 54(b) | J17: 54(a) | K17: 54(d)
C18: N/A | D18: 26-45 | G18: 152-158 | J18: 152-158 | K18: 152-158
G19: =template_label_has_the_undertaking_has_established_ghg_emission_reduction_targets | J19: TRUE
D20: =template_label_current_reporting_period | G20: =template_label_base_year | J20: =template_label_target_year | K20: =template_label_percentage_reduction_from_base_year
A21: =template_label_GHG_calculator | C21: =template_label_year_date | D21: =IF('General Information'!$D$9="", "-", 'General Information'!$D$9) & " - " & IF('General Information'!$D$13="", "-", 'General Information'!$D$13) | G21: 2020 | J21: 2030 | L21: =IF(AND(J19=TRUE, G21<>"", J21<>""), template_label_ok, IF(AND(J19=TRUE, G21="", J21=""), template_label_missing_value, IF(AND(J19=FALSE, G21="", J21=""), "", IF(AND(J19=TRUE, OR(G21="", J21="")), template_label_missing_value, ""))))
C22: =template_label_gross_scope_1_ghg_emissions | D22: 100 | G22: 150 | J22: 75 | K22: =IF(AND(G22="", J22=""), "-", IFERROR(-(1 - (J22 / G22)), "-")) | L22: =IF(OR( 'Table of Contents & Validation'!D23=TRUE,'Table of Contents & Validation'!D20=TRUE), IF(AND(OR(BasisForPreparation="Option A (Basic Module Only)", BasisForPreparation="Option B (Basic Module and Comprehensive Module)"), D22="", J19=FALSE), "", IF(AND(OR(BasisForPreparation="Option A (Basic Module Only)", BasisForPreparation="Option B (Basic Module and Comprehensive Module)"), D22<>"", G22<>"", J22<>"", J19=TRUE), template_label_ok, IF(AND(BasisForPreparation="Option A (Basic Module Only)", D22<>"", OR(G22="", J22=""), J19=FALSE), template_label_ok, IF(AND(BasisForPreparation="Option A (Basic Module Only)", D22<>"", OR(G22="", J22=""), J19=TRUE), template_label_missing_value, IF(AND(BasisForPreparation="Option B (Basic Module and Comprehensive Module)", D22<>"", OR(G22="", J22=""), J19=TRUE), template_label_missing_value, IF(AND(BasisForPreparation="Option B (Basic Module and Comprehensive Module)", D22="", OR(G22="", J22=""), J19=TRUE), template_label_missing_value, IF(AND(BasisForPreparation="Option A (Basic Module Only)", D22<>"", G22="", J22="", J19=FALSE), template_label_ok, IF(AND(BasisForPreparation="Option B (Basic Module and Comprehensive Module)", D22<>"", G22="", J22="", J19=FALSE), template_label_ok, IF(OR(BasisForPreparation="", D22="", G22="", J22="", J19=FALSE), "", template_label_missing_value))))))))), IF(AND(OR(BasisForPreparation="Option A (Basic Module Only)", BasisForPreparation="Option B (Basic Module and Comprehensive Module)"), D22="", J19=FALSE), template_label_missing_value, IF(AND(OR(BasisForPreparation="Option A (Basic Module Only)", BasisForPreparation="Option B (Basic Module and Comprehensive Module)"), D22<>"", G22<>"", J22<>"", J19=TRUE), template_label_ok, IF(AND(BasisForPreparation="Option A (Basic Module Only)", D22<>"", OR(G22="", J22=""), J19=FALSE), template_label_ok, IF(AND(BasisForPreparation="Option A (Basic Module Only)", D22<>"", OR(G22="", J22=""), J19=TRUE), template_label_missing_value, IF(AND(BasisForPreparation="Option B (Basic Module and Comprehensive Module)", D22<>"", OR(G22="", J22=""), J19=TRUE), template_label_missing_value, IF(AND(BasisForPreparation="Option B (Basic Module and Comprehensive Module)", D22="", OR(G22="", J22=""), J19=TRUE), template_label_missing_value, IF(AND(BasisForPreparation="Option A (Basic Module Only)", D22<>"", G22="", J22="", J19=FALSE), template_label_ok, IF(AND(BasisForPreparation="Option B (Basic Module and Comprehensive Module)", D22<>"", G22="", J22="", J19=FALSE), template_label_ok, IF(OR(BasisForPreparation="", D22="", G22="", J22="", J19=FALSE), "", template_label_missing_value))))))))) )
C23: =template_label_gross_scope_2_location_based_ghg_emissions | D23: 50 | G23: 75 | J23: 15 | K23: =IF(AND(G23="", J23=""), "-", IFERROR(-(1 - (J23 / G23)), "-")) | L23: =IF(OR( 'Table of Contents & Validation'!D23=TRUE,'Table of Contents & Validation'!D20=TRUE), IF(AND(OR(BasisForPreparation="Option A (Basic Module Only)", BasisForPreparation="Option B (Basic Module and Comprehensive Module)"), D23="", J19=FALSE), "", IF(AND(OR(BasisForPreparation="Option A (Basic Module Only)", BasisForPreparation="Option B (Basic Module and Comprehensive Module)"), D23<>"", G23<>"", J23<>"", J19=TRUE), template_label_ok, IF(AND(BasisForPreparation="Option A (Basic Module Only)", D23<>"", OR(G23="", J23=""), J19=FALSE), template_label_ok, IF(AND(BasisForPreparation="Option A (Basic Module Only)", D23<>"", OR(G23="", J23=""), J19=TRUE), template_label_missing_value, IF(AND(BasisForPreparation="Option B (Basic Module and Comprehensive Module)", D23<>"", OR(G23="", J23=""), J19=TRUE), template_label_missing_value, IF(AND(BasisForPreparation="Option B (Basic Module and Comprehensive Module)", D23="", OR(G23="", J23=""), J19=TRUE), template_label_missing_value, IF(AND(BasisForPreparation="Option A (Basic Module Only)", D23<>"", G23="", J23="", J19=FALSE), template_label_ok, IF(AND(BasisForPreparation="Option B (Basic Module and Comprehensive Module)", D23<>"", G23="", J23="", J19=FALSE), template_label_ok, IF(OR(BasisForPreparation="", D23="", G23="", J23="", J19=FALSE), "", template_label_missing_value))))))))), IF(AND(OR(BasisForPreparation="Option A (Basic Module Only)", BasisForPreparation="Option B (Basic Module and Comprehensive Module)"), D23="", J19=FALSE), template_label_missing_value, IF(AND(OR(BasisForPreparation="Option A (Basic Module Only)", BasisForPreparation="Option B (Basic Module and Comprehensive Module)"), D23<>"", G23<>"", J23<>"", J19=TRUE), template_label_ok, IF(AND(BasisForPreparation="Option A (Basic Module Only)", D23<>"", OR(G23="", J23=""), J19=FALSE), template_label_ok, IF(AND(BasisForPreparation="Option A (Basic Module Only)", D23<>"", OR(G23="", J23=""), J19=TRUE), template_label_missing_value, IF(AND(BasisForPreparation="Option B (Basic Module and Comprehensive Module)", D23<>"", OR(G23="", J23=""), J19=TRUE), template_label_missing_value, IF(AND(BasisForPreparation="Option B (Basic Module and Comprehensive Module)", D23="", OR(G23="", J23=""), J19=TRUE), template_label_missing_value, IF(AND(BasisForPreparation="Option A (Basic Module Only)", D23<>"", G23="", J23="", J19=FALSE), template_label_ok, IF(AND(BasisForPreparation="Option B (Basic Module and Comprehensive Module)", D23<>"", G23="", J23="", J19=FALSE), template_label_ok, IF(OR(BasisForPreparation="", D23="", G23="", J23="", J19=FALSE), "", template_label_missing_value))))))))) )
C24: =template_label_gross_scope_2_market_based_ghg_emissions & " - " & template_label_may_not_headline | K24: =IF(AND(G24="", J24=""), "-", IFERROR(-(1 - (J24 / G24)), "-")) | L24: =IF(D24<>"", IF(AND(G24="", J24=""), template_label_ok, IF(AND(G24<>"", J24=""), template_label_missing_value, template_label_ok) ), "")
C25: =template_label_total_scope_1_and_scope_2_ghg_emissions_location_based | K25: =IF(AND(G25="", J25=""), "-", IFERROR(-(1 - (J25 / G25)), "-"))
C26: =template_label_total_scope_1_and_scope_2_ghg_emissions_market_based & " - " & template_label_may_not_headline | K26: =IF(AND(G26="", J26=""), "-", IFERROR(-(1 - (J26 / G26)), "-"))
C27: 50-53 | G27: 54
C28: N/A | D28: 150-151 | G28: N/A | J28: N/A
C29: =template_label_is_the_undertaking_disclosing_entity_specific_information_on_scope_3_emissions | G29: TRUE
C30: =template_label_1_purchased_goods_and_services | D30: 200 | G30: 300 | J30: 100 | K30: =IF(OR(G30="", J30=""), "-", IFERROR(-(1 - (J30 / G30)), "-")) | L30: {=IF( OR( SUMPRODUCT((G30:G44<>"")*(J30:J44="")) > 0, SUMPRODUCT((J30:J44<>"")*(G30:G44="")) > 0 ), template_label_missing_value, IF( AND(G29=TRUE, COUNTA(D30:F44)=0), template_label_missing_value, IF(G29=FALSE, "", template_label_ok) ) )} | M30: =template_label_scope_3_categories_warning
C31: =template_label_2_capital_goods | K31: =IF(OR(G31="", J31=""), "-", IFERROR(-(1 - (J31 / G31)), "-"))
C32: =template_label_3_fuel__and_energy_related_activities | K32: =IF(OR(G32="", J32=""), "-", IFERROR(-(1 - (J32 / G32)), "-"))
C33: =template_label_4_upstream_transportation_and_distribution | K33: =IF(OR(G33="", J33=""), "-", IFERROR(-(1 - (J33 / G33)), "-"))
C34: =template_label_5_waste_generated_in_operations | K34: =IF(OR(G34="", J34=""), "-", IFERROR(-(1 - (J34 / G34)), "-"))
C35: =template_label_6_business_travel | K35: =IF(OR(G35="", J35=""), "-", IFERROR(-(1 - (J35 / G35)), "-"))
C36: =template_label_7_employee_commuting | K36: =IF(OR(G36="", J36=""), "-", IFERROR(-(1 - (J36 / G36)), "-"))
C37: =template_label_8_upstream_leased_assets | K37: =IF(OR(G37="", J37=""), "-", IFERROR(-(1 - (J37 / G37)), "-"))
C38: =template_label_9_downstream_transportation_and_distribution | D38: 500 | G38: 400 | J38: 200 | K38: =IF(OR(G38="", J38=""), "-", IFERROR(-(1 - (J38 / G38)), "-"))
C39: =template_label_10_processing_of_sold_products | K39: =IF(OR(G39="", J39=""), "-", IFERROR(-(1 - (J39 / G39)), "-"))
C40: =template_label_11_use_of_sold_products | K40: =IF(OR(G40="", J40=""), "-", IFERROR(-(1 - (J40 / G40)), "-"))
C41: =template_label_12_end_of_life_treatment_of_sold_products | K41: =IF(OR(G41="", J41=""), "-", IFERROR(-(1 - (J41 / G41)), "-"))
C42: =template_label_13_downstream_leased_assets | K42: =IF(OR(G42="", J42=""), "-", IFERROR(-(1 - (J42 / G42)), "-"))
...

Sheet Social Disclosures
A1: =template_label_paragraph_reference | B1: =template_label_paragraph_guidance_reference
C2: =template_label_employee_counting_methodology_for_the_disclosures_below_headcount_full_time_equivalent | F2: =IF('General Information'!$E$284="","-",'General Information'!$E$284)
C3: =template_label_employee_counting_methodology_for_the_disclosures_below_period | F3: =IF('General Information'!$E$283="","-",'General Information'!$E$283)
C6: =template_label_b8_workforce_general_characteristics_type_of_contract&" "&template_label_always_to_be_reported
C7: 39(a)
C8: 110-117
C9: =template_label_type_of_contract | D9: =template_label_number_of_employees
C10: =template_label_permanent_contract | D10: 110 | H10: =IF(OR( 'Table of Contents & Validation'!D38=TRUE,'Table of Contents & Validation'!D37=TRUE), IF( AND( OR( 'General Information'!E122="Option A (Basic Module only)", 'General Information'!E122="Option B (Basic Module and Comprehensive Module)" ), D10="" ), "", IF('General Information'!E122="", "", template_label_ok ) ), IF( AND( OR( 'General Information'!E122="Option A (Basic Module only)", 'General Information'!E122="Option B (Basic Module and Comprehensive Module)" ), D10="" ), template_label_missing_value, IF('General Information'!E122="", "", template_label_ok ) ) )
C11: =template_label_temporary_contract
C12: =template_label_total_employees | D12: =IF('General Information'!$E$282="", "-", VALUE(SUBSTITUTE('General Information'!$E$282, "-", "0")))
C14: =template_label_b8_workforce_general_characteristics_gender&" "&template_label_always_to_be_reported
C15: 39(b)
C16: 110-117
C17: =template_label_gender | D17: =template_label_number_of_employees
