Workbook
Name AddressOfSite: 'General Information'!$D$109:$D$133
Name AmountOfEmissionsTable: 'Environmental Disclosures'!$D$80:$K$119
Name AmountOfEmissionToAir: 'Environmental Disclosures'!$G$80:$I$119
Name AmountOfEmissionToAir_unit: 'Environmental Disclosures'!$C$78
Name AmountOfEmissionToSoil: 'Environmental Disclosures'!$K$80:$K$119
Name AmountOfEmissionToSoil_unit: 'Environmental Disclosures'!$C$78
Name AmountOfEmissionToWater: 'Environmental Disclosures'!$J$80:$J$119
Name AmountOfEmissionToWater_unit: 'Environmental Disclosures'!$C$78
Name AmountOfWaterWithdrawnAtSitesLocatedInAreasOfHighWaterStress: '[1]Environmental Disclosures'!$D$170
Name AmountOfWaterWithdrawnAtSitesLocatedInAreasOfHighWaterStress: 'Environmental Disclosures'!$D$170
Name AreaOfSiteInBiodiversitySensitiveArea: 'Environmental Disclosures'!$G$128:$I$153
Name AreaOfSiteInBiodiversitySensitiveArea_unit: 'Environmental Disclosures'!$C$126
Name Assets: 'General Information'!$E$60
Name AverageNumberOfAnnualTrainingHoursPerFemaleEmployee: 'Social Disclosures'!$D$68
Name AverageNumberOfAnnualTrainingHoursPerMaleEmployee: 'Social Disclosures'!$D$67
Name AverageNumberOfAnnualTrainingHoursPerNonReportedGenderEmployee: 'Social Disclosures'!$D$70
Name AverageNumberOfAnnualTrainingHoursPerOtherGenderEmployee: 'Social Disclosures'!$D$69
Name BaselineYearMember: 'Environmental Disclosures'!$G$21
Name BasisForPreparation: '[1]General Information'!$E$32
Name BasisForPreparation: 'General Information'!$E$32
Name BasisForReporting: '[1]General Information'!$E$42
Name BasisForReporting: 'General Information'!$E$42
Name BreakdownOfAnnualMassFlowOfRelevantMaterialsUsedByTheUndertakingHypercube: 'Environmental Disclosures'!$C$216:$I$230
Name BreakdownOfEnergyConsumptionAxis: 'Environmental Disclosures'!$C$12:$F$14
Name BreakdownOfEnergyConsumptionTable: 'Environmental Disclosures'!$G$12:$K$14
Name CityOfSite: 'General Information'!$F$109:$F$133
Name CountryOfEmploymentContractAxis: 'Social Disclosures'!$C$29:$D$38
Name CountryOfPrimaryOperationsAndLocationOfSignificantAssets: 'General Information'!$E$65
Name CountryOfSite: 'General Information'!$G$109:$G$133
Name DateOfAdoptionOfTransitionPlanForUndertakingNotHavingAdoptedTransitionPlanYet: 'Environmental Disclosures'!$D$62
Name DescriptionOfActionsTakeToAddressTheConfirmedIncidents: 'Social Disclosures'!$D$102
Name DescriptionOfATargetRelatedToAPolicy: 'General Information'!$E$150
Name DescriptionOfATransitionPlanForClimateChangeMitigationIncludingAnExplanationOfHowItIsContributingToReduceGhgEmissions: '[1]Environmental Disclosures'!$D$58
Name DescriptionOfATransitionPlanForClimateChangeMitigationIncludingAnExplanationOfHowItIsContributingToReduceGhgEmissions: 'Environmental Disclosures'!$D$58
Name DescriptionOfClimateRelatedHazardsAndClimateRelatedTransitionEvents: 'Environmental Disclosures'!$E$236
Name DescriptionOfHowCircularEconomyPrinciplesAreApplied: 'Environmental Disclosures'!$D$183
Name DescriptionOfKeyElementsOfStrategyThatRelatesToOrAffectsSustainabilityIssues: 'General Information'!$E$161
Name DescriptionOfLimitsToTheDistributionOfProfitsConnectedToTheMutualisticNatureOrToTheNatureOfTheActivitiesConsistingInServicesOfGeneralEconomicInterestSGEI: 'General Information'!$D$146
Name DescriptionOfMainBusinessRelationships: 'General Information'!$E$157
Name DescriptionOfPracticesPoliciesAndOrFutureInitiatives: '[1]General Information'!$E$148
Name DescriptionOfPracticesPoliciesAndOrFutureInitiatives: 'General Information'!$E$149
Name DescriptionOfSignificantGroupsOfProductsAndOrServicesOffered: 'General Information'!$E$155
Name DescriptionOfSignificantMarketsTheUndertakingOperatesIn: 'General Information'!$E$156
Name DescriptionOfSustainabilityRelatedCertificationsOrLabels: 'General Information'!$E$100
Name DescriptionOfTheEffectiveParticipationOfWorkersUsersOrOtherInterestedPartiesOrCommunitiesInGovernance: 'General Information'!$D$144
Name DisclosureOfAnyOtherEnvironmentalAndOrEntitySpecificEnvironmentalDisclosures: 'Environmental Disclosures'!$C$244
Name DisclosureOfAnyOtherGeneralAndOrEntitySpecificInformation: 'General Information'!$C$165
Name DisclosureOfAnyOtherGovernanceAndOrEntitySpecificGovernanceDisclosures: 'Governance Disclosures'!$C$38
Name DisclosureOfAnyOtherSocialAndOrEntitySpecificSocialDisclosures: 'Social Disclosures'!$C$110
Name DisclosureOfHowItHasAssessedTheExposureAndSensitivityOfItsAssetsActivitiesAndValueChainToTheseHazardsAndTransitionEvents: 'Environmental Disclosures'!$E$237
Name DisclosureOfListOfMainActionsTheEntitySeeksInOrderToAchieveItsTargets: 'Environmental Disclosures'!$C$52
Name DisclosureOfWhetherItHasUndertakenClimateChangeAdaptationActionsForAnyClimateRelatedHazardsAndTransitionEvents: 'Environmental Disclosures'!$E$239
Name EmployeeCountingMethodology: 'General Information'!$E$63
Name EmployeesReceivePayEqualOrAboveMinimumWageDeterminedByNationalLawOrCollectiveAgreement: '[1]Social Disclosures'!$D$56
Name EmployeesReceivePayEqualOrAboveMinimumWageDeterminedByNationalLawOrCollectiveAgreement: 'Social Disclosures'!$D$57
Name EmployeeTurnoverRate: 'Social Disclosures'!$D$47
Name EnergyConsumptionFromElectricity_NonRenewableEnergyMember: 'Environmental Disclosures'!$J$12
Name EnergyConsumptionFromElectricity_RenewableEnergyMember: 'Environmental Disclosures'!$G$12
Name EnergyConsumptionFromElectricity_TotalRenewableAndNonRenewableEnergyMember: 'Environmental Disclosures'!$K$12
Name EnergyConsumptionFromFuels_NonRenewableEnergyMember: 'Environmental Disclosures'!$J$14

Sheet Cover Page Template Sample
B2: VSME Digital Template Sample
B24: Disclaimer: This Excel template is intended for demonstration purposes only. All entities, names, data, and related information contained herein are entirely fictitious. Any resemblance to actual companies or individuals is purely coincidental. This sample should not be interpreted as reflecting real-world data or business. practices.

Sheet Introduction
B1: =template_label_version -> Version: | C1: 1.1.0
B2: =template_label_publication_date -> Publication date: | C2: 45933
B3: {=IF(ISERROR(CELL("filename",A1)),"Warning: The Digital Template was developed and tested using Microsoft Excel 365. Functionality may be limited or incorrect when using other spreadsheet applications or older versions of Excel.","")}
B10: =template_label_taxonomy_entry_point -> Taxonomy entry point: | C10: https://xbrl.efrag.org/taxonomy/vsme/2025-07-30/vsme-all.xsd
B11: =template_label_select_template_display_language -> Select Template Display Language: | C11: English - Official [en]
B12: =template_label_title_of_report -> Main title of the report | C12: =template_label_main_title_of_report_text -> Sustainability Report
B13: =template_label_subtitle_of_report -> Subtitle of the report | C13: =template_label_subtitle_of_report_text -> Prepared in accordance with the Voluntary Sustainability Reporting Standard for small and medium-sized undertakings (VSME), released by the European Commission on 30 July 2025.
B14: =template_label_vsme_digital_template -> VSME Digital Template
B15: =template_label_the_purpose_of_this_digital_template_is_to_illustrate_how_vsme_reporting_can_be_implemented_in_a_digital_template -> The purpose of this digital template is to illustrate how VSME reporting can be implemented in a digital template. The template reflects the VSME Recommendation as published by the European Commission on 30 July 2025. The template is accompanied by a digital VSME XBRL taxonomy, which represents the digital data model of the disclosures and is available on EFRAG's website. The VSME requires disclosure of comparative information on metrics (paragraph 12). This template enables reporting for one reporting period only. Therefore, it might be used for reporting in the first year only. It is expected that reporting solutions will enable the roll-forward of reporting periods, which would automatically provide the necessary comparative information. This template can be used for data entry and validation. By using an XBRL Converter on EFRAG's website, it can be saved as an XBRL report, in a free and open data format. Excel-named ranges are used to extract the disclosures. Value cells that are empty and do not have any value (neither text nor a number) will not be considered as reported and will not be included in the XBRL report when using the Excel-to-XBRL converter. A few drop-down selection menus in the VSME have more than 100 entries (e.g. the NACE codes under B1, the list of pollutants under B4, the list of wastes under B7). In order to search in the list, users can simply start typing search keywords in the cell. If a security warning is shown, please "Enable Content" in order to allow automatic calculation of GPS coordinates for the list of sites under B1. No content other than the address entered will be sent to the internet and the contents shared with the provider can be found in the Nominatim Usage Policy (Geocoding Policy) and Privacy Policy. All materials developed by the EFRAG Secretariat are released for free and as open source (MIT license), which will enable any stakeholder to further enhance them and integrate them into commercial solutions. However, respecting the license conditions, the reference to EFRAG must be mentioned by the providers of those commercial solutions. It's possible to consult the MIT License in the specific sheet. If you wish to raise an issue with the VSME Digital Template or the Digital Template to XBRL Converter, please do so by creating an issue in the GitHub project.
B18: =template_label_how_to_use_it -> How to use it:
B19: =template_label_0_provide_information_that_is_mandatory_in_order_to_generate_the_vsme_and_xbrl_report -> 0. Provide information that is mandatory in order to generate the VSME and XBRL Report.
B20: =template_label_1_fill_in_the_disclosures_on_the_four_worksheets -> 1. Fill in the disclosures on the four worksheets (General Information, Environmental Disclosures, Social Disclosures, Governance Disclosures) in the white cells framed by a black border. Do not enter information outside of those cells. Searching in drop-downs can be done by typing into the cell. Hints (input messages) are shown in several cells when selecting them.
B21: =template_label_2_find_more_information_on_the_actual_disclosure_requirements_in_the_vsme_standard -> 2. Find more information on the actual disclosure requirements in the VSME Standard and the related guidance linked to each cell. Additional or entity-specific disclosures can be provided in each text box at the end of each worksheet.
B22: =template_label_3_for_open_tables_like_the_list_of_subsidizers_sites_please_expand_the_groups_by_clicking_the_plus -> 3. For open tables like the List of subsidiaries/sites, please expand the groups by clicking the plus [+] icon on the left side. If more rows are needed, they can be added by inserting them between the first and last row. The row IDs in open tables must remain unique per table.
B23: =template_label_4_validate_the_data_entered_by_checking_the_validation_status -> 4. Validate the data entered by checking the validation status. The report is considered incomplete or erroneous if the validation fails, which might result in an invalid XBRL report.
B24: =template_label_5_convert_this_template_to_an_inline_xbrl_report -> 5. Convert this template to an Inline XBRL report (or XBRL-JSON, XBRL-CSV), using the online converter. Pay attention to the XBRL validation performed by the validator.
B25: =template_label_6_the_undertaking_may_also_upload_the_report_to_public_repositories_or_a_webpage -> 6. The undertaking may also upload the report to public repositories or a webpage.
B27: =template_label_cell_background_color_index -> Cell background color index:
B28: =template_label_general_principles -> General Principles | C28: =template_label_indicates_that_the_disclosure_is_from_the_general_principles_of_the_vsme -> Indicates that the disclosure is from the general principles of the VSME.
B29: =template_label_basic_module -> Basic Module | C29: =template_label_indicates_that_the_disclosure_is_from_the_vsme_basic_module -> Indicates that the disclosure is from the VSME Basic Module.
B30: =template_label_comprehensive_module -> Comprehensive Module | C30: =template_label_indicates_that_the_disclosure_is_from_the_vsme_comprehensive_module -> Indicates that the disclosure is from the VSME Comprehensive Module.
C31: =template_label_indicates_that_the_cell_is_automatically_calculated_and_that_no_data_entry_is_required -> Indicates that the cell is automatically calculated and that no data entry is required.
C32: =template_label_indicates_that_the_datapoint_often_a_condition_will_not_be_included_in_the_vsme_and_digital_xbrl_report -> Indicates that the datapoint (often a condition) will not be included in the VSME and digital XBRL report. These cells are provided to facilitate the completion of the disclosure as they either trigger the applicability of the disclosure or they enable the automatic calculation of the disclosure. If the yellow cells are not being used to calculate a value, the total that is to be reported can be entered manually overwriting by the formula.
C33: =template_label_indicates_that_no_data_entry_is_required_unless_certain_logics_are_selected_in_the_disclosure_itself -> Indicates that no data entry is required unless certain logics are selected in the disclosure itself. When one of these logics is selected, then this cell will turn white.
B34: =template_label_validation_missing_value_error_velue_inconsistency_invalid_url -> Validation MISSING VALUE/ERROR/VALUE INCONSISTENCY/INVALID URL | C34: =template_label_indicates_that_either_data_entry_is_incorrect_in_terms_of_format_or_that_certain_information -> Indicates that either data entry is incorrect in terms of format or that certain information is missing in order to correctly report on the disclosure.
B35: Validation OK | C35: =template_label_indicates_that_data_entry_is_ok_and_the_undertaking_can_proceed_to_the_next_disclosure -> Indicates that data entry is OK and the undertaking can proceed to the next disclosure.
C36: =template_label_no_value_can_be_entered_in_the_cell -> No value can be entered in the cell.
B37: [+] | C37: =template_label_lists_can_be_expanded_using_the_plus_button_on_the_left -> Lists can be expanded using the plus [+] button on the left. If the number of rows is not sufficient, additional rows can be added by right clicking the second row and selecting "Insert row".
B43: =template_label_efrag_is_funded_by_the_european_union_through_the_single_market_programme -> EFRAG is funded by the European Union through the Single Market Programme in which the EEA-EFTA countries (Norway, Iceland and Liechtenstein), as well as Kosovo participate. Any views and opinions expressed are however those of the author(s) only and do not necessarily reflect those of the European Union, the European Commission or of countries that participate in the Single Market Programme. Neither the European Union, the European Commission nor countries participating in the Single market Programme can be held responsible for them. © 2025 EFRAG All rights reserved.
B44: =template_label_reproduction_and_use_rights_are_strictly_limited -> Reproduction and use rights are strictly limited. For further details please contact efragsecretariat@efrag.org

Sheet Table of Contents & Validation
C2: =template_label_overall_validation_status_validation -> Overall Validation Status
B3: =template_label_table_of_contents_validation -> Table of Contents | C3: {=IF(SUMPRODUCT(--((C5:C68<>template_label_ok)*(C5:C68<>"-")*(C5:C68<>""))) > 0, template_label_incomplete, template_label_complete)} -> COMPLETE
B4: =template_label_contents_grouping_follows_templates_framework -> Contents grouping follows template's framework | C4: =template_label_specific_content_validation_status_validation -> Specific Content Validation Status
B5: =template_label_general_information_validation -> General Information
B6: =template_label_information_on_the_report_necessary_for_xbrl_validation -> · Information on the report necessary for XBRL | C6: =IF( AND( COUNTIF('General Information'!F3:F12, template_label_missing_value) > 0, COUNTIF('General Information'!F3:F12, template_label_error) = 0 ), template_label_missing_value, IF( AND( COUNTIF('General Information'!F3:F12, template_label_error) > 0, COUNTIF('General Information'!F3:F12, template_label_missing_value) = 0 ), template_label_value_inconsistency, IF( AND( COUNTIF('General Information'!F3:F12, template_label_error) > 0, COUNTIF('General Information'!F3:F12, template_label_missing_value) > 0 ), template_label_error_plus_value_inconsistency, template_label_ok ) ) ) -> OK
B7: =template_label_information_on_previous_reporting_period_validation -> · Information on previous reporting period | C7: =IF(COUNTIF('General Information'!F18:F29, template_label_missing_value) > 0, template_label_missing_value, IF(COUNTIF('General Information'!F18:F29, template_label_invalid_url ) > 0, template_label_invalid_url, IF(COUNTIF('General Information'!F18:F29, template_label_ok) > 0, template_label_ok, "-"))) -> OK
B8: =template_label_basic_module_validation -> Basic Module
B9: =template_label_general_information_validation -> General Information
B10: =template_label_b1_basis_for_preparation_validation -> · B1 - Basis for Preparation | C10: =IF(COUNTIF(C11:C14,template_label_error_plus_missing_value_plus_value_inconsistency)>0,template_label_error_plus_missing_value_plus_value_inconsistency, IF(COUNTIF(C11:C14,template_label_error_plus_value_inconsistency)>0,template_label_error_plus_value_inconsistency, IF(COUNTIF(C11:C14,template_label_error_plus_missing_value)>0,template_label_error_plus_missing_value, IF(COUNTIF(C11:C14,template_label_error)>0,template_label_error, IF(COUNTIF(C11:C14,template_label_missing_value_plus_value_inconsistency)>0,template_label_missing_value_plus_value_inconsistency, IF(COUNTIF(C11:C14,template_label_value_inconsistency)>0,template_label_value_inconsistency, IF(COUNTIF(C11:C14,template_label_missing_value)>0,template_label_missing_value, IF(COUNTIF(C11:C14,template_label_ok)=ROWS(C11:C14),template_label_ok, IF(COUNTIF(C11:C14,"-")=ROWS(C11:C14),"-", template_label_ok))))))))) -> OK
B11: =template_label_basis_for_preparation_and_other_undertakings_general_information_validation -> Basis for Preparation and other undertaking's general information | C11: =IF( AND( COUNTIF('General Information'!F32:F65, template_label_missing_value) > 0, COUNTIF('General Information'!F32:F65, template_label_value_inconsistency) = 0 ), template_label_missing_value, IF( AND( COUNTIF('General Information'!F32:F65, template_label_value_inconsistency) > 0, COUNTIF('General Information'!F32:F65, template_label_missing_value) = 0 ), template_label_value_inconsistency, IF( AND( COUNTIF('General Information'!F32:F65, template_label_value_inconsistency) > 0, COUNTIF('General Information'!F32:F65, template_label_missing_value) > 0 ), template_label_error_plus_value_inconsistency, template_label_ok ) ) ) -> OK
B12: =template_label_list_of_subsidiaries_validation -> List of subsidiaries | C12: =IF( COUNTIF('General Information'!F70:F94, template_label_missing_value) > 0, template_label_missing_value, IF( COUNTIF('General Information'!F70:F94, template_label_ok) > 0, template_label_ok, "-" ) ) -> OK
B13: =template_label_disclosure_of_sustainability_related_certifications_or_labels_validation -> Disclosure of sustainability-related certification(s) or label(s) | C13: =IF( COUNTIF('General Information'!I100, template_label_missing_value) > 0, template_label_missing_value, IF( COUNTIF('General Information'!I100, template_label_ok) > 0, template_label_ok, "-" ) ) -> OK
B14: =template_label_list_of_sites_validation -> List of site(s) | C14: =IF( COUNTIF('General Information'!I109:I133, template_label_missing_value) > 0, template_label_missing_value, IF( COUNTIF('General Information'!I109:I133, template_label_ok) > 0, template_label_ok, "-" ) ) -> OK
B15: =template_label_b2_practices_policies_and_future_initiatives_for_transitioning_towards_a_more_sustainable_economy_validation -> · B2 - Practices, policies and future initiatives for transitioning towards a more sustainable economy | C15: =IF( COUNTIF(C16:C17, template_label_error_plus_missing_value_plus_value_inconsistency) > 0, template_label_error_plus_missing_value_plus_value_inconsistency, IF( COUNTIF(C16:C17, template_label_error_plus_value_inconsistency) > 0, template_label_error_plus_value_inconsistency, IF( COUNTIF(C16:C17, template_label_error_plus_missing_value) > 0, template_label_error_plus_missing_value, IF( COUNTIF(C16:C17, template_label_error) > 0, template_label_error, IF( COUNTIF(C16:C17, template_label_missing_value_plus_value_inconsistency) > 0, template_label_missing_value_plus_value_inconsistency, IF( COUNTIF(C16:C17, template_label_value_inconsistency) > 0, template_label_value_inconsistency, IF( COUNTIF(C16:C17, template_label_missing_value) > 0, template_label_missing_value, IF( COUNTIF(C16:C17, template_label_ok) = ROWS(C16:C17), template_label_ok, IF( COUNTIF(C16:C17, "-") = ROWS(C16:C17), "-", template_label_ok ) ) ) ) ) ) ) ) ) -> OK
B16: =template_label_practices_policies_and_future_initiatives_for_transitioning_towards_a_more_sustainable_economy_validation -> Practices, policies and future initiatives for transitioning towards a more sustainable economy | C16: =IF( COUNTIF('General Information'!P140, template_label_missing_value) > 0, template_label_missing_value, IF( COUNTIF('General Information'!P140, template_label_ok) > 0, template_label_ok, "-" ) ) -> OK
B17: =template_label_cooperative_specific_disclosures_validation -> Cooperative specific disclosures | C17: {=IF(OR('General Information'!E144:E146=template_label_ok),template_label_ok,"-")} -> -
B18: =template_label_environmental_disclosures_validation -> Environmental Disclosures
B19: =template_label_b3_energy_and_greenhouse_gas_emissions_validation -> · B3 - Energy and greenhouse gas emissions | C19: =IF(COUNTIF(C20:C23,template_label_error_plus_missing_value_plus_value_inconsistency)>0,template_label_error_plus_missing_value_plus_value_inconsistency, IF(COUNTIF(C20:C23,template_label_error_plus_value_inconsistency)>0,template_label_error_plus_value_inconsistency, IF(COUNTIF(C20:C23,template_label_error_plus_missing_value)>0,template_label_error_plus_missing_value, IF(COUNTIF(C20:C23,template_label_error)>0,template_label_error, IF(COUNTIF(C20:C23,template_label_missing_value_plus_value_inconsistency)>0,template_label_missing_value_plus_value_inconsistency, IF(COUNTIF(C20:C23,template_label_value_inconsistency)>0,template_label_value_inconsistency, IF(COUNTIF(C20:C23,template_label_missing_value)>0,template_label_missing_value, IF(COUNTIF(C20:C23,template_label_ok)=ROWS(C20:C23),template_label_ok, IF(COUNTIF(C20:C23,"-")=ROWS(C20:C23),"-", template_label_ok))))))))) -> OK
B20: =template_label_total_energy_consumption_in_mwh_validation -> Total Energy Consumption (in MWh) | C20: =IF(COUNTIF('Environmental Disclosures'!L5,template_label_missing_value)>0,template_label_missing_value, IF(COUNTIF('Environmental Disclosures'!L5,template_label_ok)>0,template_label_ok,"-")) -> OK
B21: =template_label_breakdown_of_energy_consumption_in_mwh_validation -> Breakdown of energy consumption (in MWh) | C21: =IF( AND( COUNTIF('Environmental Disclosures'!L12:L14,template_label_missing_value)>0, COUNTIF('Environmental Disclosures'!L12:L14,template_label_value_inconsistency)=0 ), template_label_missing_value, IF( AND( COUNTIF('Environmental Disclosures'!L12:L14,template_label_value_inconsistency)>0, COUNTIF('Environmental Disclosures'!L12:L14,template_label_missing_value)=0 ), template_label_value_inconsistency, IF( AND( COUNTIF('Environmental Disclosures'!L12:L14,template_label_value_inconsistency)>0, COUNTIF('Environmental Disclosures'!L12:L14,template_label_missing_value)>0 ), template_label_error_plus_value_inconsistency, IF( COUNTA('Environmental Disclosures'!L12:L14,"-"), "-", template_label_ok ) ) )) -> -
B22: =template_label_estimated_greenhouse_gas_emissions_considering_the_ghg_protocol_version_2004_in_tco2e_validation -> Estimated Greenhouse Gas Emissions considering the GHG Protocol Version 2004 (in tCO2e) | C22: =IF(COUNTIF('Environmental Disclosures'!L21:L44,template_label_missing_value)>0,template_label_missing_value, IF(COUNTIF('Environmental Disclosures'!L21:L44,template_label_ok)>0,template_label_ok,"-")) -> OK
B23: =template_label_greenhouse_gas_emission_intensity_per_turnover_validation -> Greenhouse gas emission intensity per turnover | C23: =IF(C22=template_label_ok,template_label_ok,"-") -> OK
B24: =template_label_b4_pollution_of_air_water_and_soil_validation -> · B4 - Pollution of air, water and soil | C24: =IF(COUNTIF('Environmental Disclosures'!L75:L119,template_label_invalid_url)>0, template_label_invalid_url, IF(AND(COUNTIF('Environmental Disclosures'!L75:L119,template_label_missing_value)>0, COUNTIF('Environmental Disclosures'!L75:L119,template_label_value_inconsistency)>0), template_label_missing_value_plus_value_inconsistency, IF(COUNTIF('Environmental Disclosures'!L75:L119,template_label_missing_value)>0, template_label_missing_value, IF(COUNTIF('Environmental Disclosures'!L75:L119,template_label_value_inconsistency)>0, template_label_value_inconsistency, IF(COUNTIF('Environmental Disclosures'!L75:L119,template_label_ok)>0, template_label_ok, "-"))))) -> OK
B25: =template_label_b5_biodiversity_validation -> · B5 - Biodiversity | C25: =IF(COUNTIF(C26:C27,template_label_error_plus_missing_value_plus_value_inconsistency)>0,template_label_error_plus_missing_value_plus_value_inconsistency, IF(COUNTIF(C26:C27,template_label_error_plus_value_inconsistency)>0,template_label_error_plus_value_inconsistency, IF(COUNTIF(C26:C27,template_label_error_plus_missing_value)>0,template_label_error_plus_missing_value, IF(COUNTIF(C26:C27,template_label_error)>0,template_label_error, IF(COUNTIF(C26:C27,template_label_missing_value_plus_value_inconsistency)>0,template_label_missing_value_plus_value_inconsistency, IF(COUNTIF(C26:C27,template_label_value_inconsistency)>0,template_label_value_inconsistency, IF(COUNTIF(C26:C27,template_label_missing_value)>0,template_label_missing_value, IF(COUNTIF(C26:C27,template_label_ok)=ROWS(C26:C27),template_label_ok, IF(COUNTIF(C26:C27,"-")=ROWS(C26:C27),"-", template_label_ok))))))))) -> OK
B26: =template_label_sites_in_biodiversity_sensitive_areas_validation -> Sites in biodiversity sensitive areas | C26: =IF(AND( COUNTIF('Environmental Disclosures'!D128:D153,template_label_ok) + COUNTIF('Environmental Disclosures'!L126:L153,template_label_ok) > 0, COUNTIF('Environmental Disclosures'!D128:D153,template_label_missing_value) + COUNTIF('Environmental Disclosures'!L126:L153,template_label_missing_value) = 0, COUNTIF('Environmental Disclosures'!D128:D153,template_label_value_inconsistency) + COUNTIF('Environmental Disclosures'!L126:L153,template_label_value_inconsistency) = 0), template_label_ok, IF(AND( COUNTIF('Environmental Disclosures'!D128:D153,template_label_missing_value) + COUNTIF('Environmental Disclosures'!L126:L153,template_label_missing_value) > 0, COUNTIF('Environmental Disclosures'!D128:D153,template_label_value_inconsistency) + COUNTIF('Environmental Disclosures'!L126:L153,template_label_value_inconsistency) = 0), template_label_missing_value, IF(AND( COUNTIF('Environmental Disclosures'!D128:D153,template_label_value_inconsistency) + COUNTIF('Environmental Disclosures'!L126:L153,template_label_value_inconsistency) > 0, COUNTIF('Environmental Disclosures'!D128:D153,template_label_missing_value) + COUNTIF('Environmental Disclosures'!L126:L153,template_label_missing_value) = 0), template_label_value_inconsistency, IF(AND( COUNTIF('Environmental Disclosures'!D128:D153,template_label_value_inconsistency) + COUNTIF('Environmental Disclosures'!L126:L153,template_label_value_inconsistency) > 0, COUNTIF('Environmental Disclosures'!D128:D153,template_label_missing_value) + COUNTIF('Environmental Disclosures'!L126:L153,template_label_missing_value) > 0), template_label_missing_value_plus_value_inconsistency, "-" ) ) ) ) -> OK
B27: =template_label_biodiversity_land_use_validation -> Biodiversity - Land-use | C27: =IF( AND( COUNTIF('Environmental Disclosures'!G159:G164,template_label_missing_value)>0, COUNTIF('Environmental Disclosures'!G159:G164,template_label_value_inconsistency)=0, COUNTIF('Environmental Disclosures'!G159:G164,template_label_ok)>=0 ), template_label_missing_value, IF( AND( COUNTIF('Environmental Disclosures'!G159:G164,template_label_value_inconsistency)>0, COUNTIF('Environmental Disclosures'!G159:G164,template_label_missing_value)=0, COUNTIF('Environmental Disclosures'!G159:G164,template_label_ok)>=0 ), template_label_value_inconsistency, IF( AND( COUNTIF('Environmental Disclosures'!G159:G164,template_label_value_inconsistency)>0, COUNTIF('Environmental Disclosures'!G159:G164,template_label_missing_value)>0, COUNTIF('Environmental Disclosures'!G159:G164,template_label_ok)>=0 ), template_label_missing_value_plus_value_inconsistency, IF( AND( COUNTIF('Environmental Disclosures'!G159:G164,template_label_value_inconsistency)=0, COUNTIF('Environmental Disclosures'!G159:G164,template_label_missing_value)=0, COUNTIF('Environmental Disclosures'!G159:G164,template_label_ok)>0 ), template_label_ok, "-" ) ) )) -> -
B28: =template_label_b6_water_validation -> · B6 - Water | C28: =IF(COUNTIF(C29:C30,template_label_error_plus_missing_value_plus_value_inconsistency)>0,template_label_error_plus_missing_value_plus_value_inconsistency, IF(COUNTIF(C29:C30,template_label_error_plus_value_inconsistency)>0,template_label_error_plus_value_inconsistency, IF(COUNTIF(C29:C30,template_label_error_plus_missing_value)>0,template_label_error_plus_missing_value, IF(COUNTIF(C29:C30,template_label_error)>0,template_label_error, IF(COUNTIF(C29:C30,template_label_missing_value_plus_value_inconsistency)>0,template_label_missing_value_plus_value_inconsistency, IF(COUNTIF(C29:C30,template_label_value_inconsistency)>0,template_label_value_inconsistency, IF(COUNTIF(C29:C30,template_label_missing_value)>0,template_label_missing_value, IF(COUNTIF(C29:C30,template_label_ok)=ROWS(C29:C30),template_label_ok, IF(COUNTIF(C29:C30,"-")=ROWS(C29:C30),"-", template_label_ok))))))))) -> OK
B29: =template_label_water_withdrawal_validation -> Water Withdrawal | C29: =IF(COUNTIF('Environmental Disclosures'!E169:F170, template_label_missing_value) > 0, template_label_missing_value, IF(COUNTIF('Environmental Disclosures'!E169:F170, template_label_ok) > 0, template_label_ok, "-")) -> OK
B30: =template_label_water_consumption_validation -> Water Consumption | C30: =IF(COUNTIF('Environmental Disclosures'!E176:F176, template_label_missing_value) > 0, template_label_missing_value, IF(COUNTIF('Environmental Disclosures'!E176:F176, template_label_ok) > 0, template_label_ok, "-")) -> OK
B31: =template_label_b7_resource_use_circular_economy_and_waste_management_validation -> · B7 - Resource use, circular economy and waste management | C31: =IF(COUNTIF(C32:C34, template_label_error_plus_missing_value_plus_value_inconsistency) > 0, template_label_error_plus_missing_value_plus_value_inconsistency, IF(COUNTIF(C32:C34, template_label_error_plus_value_inconsistency) > 0, template_label_error_plus_value_inconsistency, IF(COUNTIF(C32:C34, template_label_error_plus_missing_value) > 0, template_label_error_plus_missing_value, IF(COUNTIF(C32:C34, template_label_error) > 0, template_label_error, IF(COUNTIF(C32:C34, template_label_missing_value_plus_value_inconsistency) > 0, template_label_missing_value_plus_value_inconsistency, IF(COUNTIF(C32:C34, template_label_value_inconsistency) > 0, template_label_value_inconsistency, IF(COUNTIF(C32:C34, template_label_missing_value) > 0, template_label_missing_value, IF(COUNTIF(C32:C34, template_label_ok) = ROWS(C32:C34), template_label_ok, IF(COUNTIF(C32:C34, "-") = ROWS(C32:C34), "-", template_label_ok))))))))) -> OK
B32: =template_label_description_of_circular_economy_principles_validation -> Description of circular economy principles | C32: =IF( AND( COUNTIF('Environmental Disclosures'!H182:I183, template_label_missing_value) > 0, COUNTIF('Environmental Disclosures'!H182:I183, template_label_value_inconsistency) = 0, COUNTIF('Environmental Disclosures'!H182:I183, template_label_ok) >= 0 ), template_label_missing_value, IF( AND( COUNTIF('Environmental Disclosures'!H182:I183, template_label_value_inconsistency) > 0, COUNTIF('Environmental Disclosures'!H182:I183, template_label_missing_value) = 0, COUNTIF('Environmental Disclosures'!H182:I183, template_label_ok) >= 0 ), template_label_value_inconsistency, IF( AND( COUNTIF('Environmental Disclosures'!H182:I183, template_label_value_inconsistency) > 0, COUNTIF('Environmental Disclosures'!H182:I183, template_label_missing_value) > 0, COUNTIF('Environmental Disclosures'!H182:I183, template_label_ok) >= 0 ), template_label_missing_value_plus_value_inconsistency, IF( AND( COUNTIF('Environmental Disclosures'!H182:I183, template_label_value_inconsistency) = 0, COUNTIF('Environmental Disclosures'!H182:I183, template_label_missing_value) = 0, COUNTIF('Environmental Disclosures'!H182:I183, template_label_ok) > 0 ), template_label_ok, "-" ) ) )) -> OK
B33: =template_label_waste_generated_validation -> Waste generated | C33: =IF( AND( COUNTIF('Environmental Disclosures'!M189:M204, template_label_error) > 0, COUNTIF('Environmental Disclosures'!M189:M204, template_label_missing_value) > 0, COUNTIF('Environmental Disclosures'!M189:M204, template_label_value_inconsistency) > 0 ), template_label_error_plus_missing_value_plus_value_inconsistency, IF( AND( COUNTIF('Environmental Disclosures'!M189:M204, template_label_error) > 0, COUNTIF('Environmental Disclosures'!M189:M204, template_label_value_inconsistency) > 0, COUNTIF('Environmental Disclosures'!M189:M204, template_label_missing_value) = 0 ), template_label_error_plus_value_inconsistency, IF( AND( COUNTIF('Environmental Disclosures'!M189:M204, template_label_error) > 0, COUNTIF('Environmental Disclosures'!M189:M204, template_label_missing_value) > 0, COUNTIF('Environmental Disclosures'!M189:M204, template_label_value_inconsistency) = 0 ), template_label_error_plus_missing_value, IF( AND( COUNTIF('Environmental Disclosures'!M189:M204, template_label_missing_value) > 0, COUNTIF('Environmental Disclosures'!M189:M204, template_label_value_inconsistency) > 0, COUNTIF('Environmental Disclosures'!M189:M204, template_label_error) = 0 ), template_label_missing_value_plus_value_inconsistency, IF( AND( COUNTIF('Environmental Disclosures'!M189:M204, template_label_error) > 0, COUNTIF('Environmental Disclosures'!M189:M204, template_label_missing_value) = 0, COUNTIF('Environmental Disclosures'!M189:M204, template_label_value_inconsistency) = 0 ), template_label_error, IF( AND( COUNTIF('Environmental Disclosures'!M189:M204, template_label_missing_value) > 0, COUNTIF('Environmental Disclosures'!M189:M204, template_label_error) = 0, COUNTIF('Environmental Disclosures'!M189:M204, template_label_value_inconsistency) = 0 ), template_label_missing_value, IF( AND( COUNTIF('Environmental Disclosures'!M189:M204, template_label_value_inconsistency) > 0, COUNTIF('Environmental Disclosures'!M189:M204, template_label_error) = 0, COUNTIF('Environmental Disclosures'!M189:M204, template_label_missing_value) = 0 ), template_label_value_inconsistency, IF( AND( COUNTIF('Environmental Disclosures'!M189:M204, template_label_error) = 0, COUNTIF('Environmental Disclosures'!M189:M204, template_label_missing_value) = 0, COUNTIF('Environmental Disclosures'!M189:M204, template_label_value_inconsistency) = 0, COUNTIF('Environmental Disclosures'!M189:M204, template_label_ok) > 0 ), template_label_ok, "-" )))))))) -> OK
B34: =template_label_annual_mass_flow_of_relevant_materials_used_validation -> Annual mass-flow of relevant materials used | C34: =IF(COUNTIF('Environmental Disclosures'!K216:K230, template_label_missing_value) > 0, template_label_missing_value, IF(COUNTIF('Environmental Disclosures'!K216:K230, template_label_ok) > 0, template_label_ok, "-")) -> OK
B35: =template_label_social_disclosures_validation -> Social Disclosures
B36: =template_label_b8_workforce_general_characteristics_validation -> · B8 - Workforce - General characteristics | C36: =IF(COUNTIF(C37:C40, template_label_error_plus_missing_value_plus_value_inconsistency) > 0, template_label_error_plus_missing_value_plus_value_inconsistency, IF(COUNTIF(C37:C40, template_label_error_plus_value_inconsistency) > 0, template_label_error_plus_value_inconsistency, IF(COUNTIF(C37:C40, template_label_error_plus_missing_value) > 0, template_label_error_plus_missing_value, IF(COUNTIF(C37:C40, template_label_error) > 0, template_label_error, IF(COUNTIF(C37:C40, template_label_missing_value_plus_value_inconsistency) > 0, template_label_missing_value_plus_value_inconsistency, IF(COUNTIF(C37:C40, template_label_value_inconsistency) > 0, template_label_value_inconsistency, IF(COUNTIF(C37:C40, template_label_missing_value) > 0, template_label_missing_value, IF(COUNTIF(C37:C40, template_label_ok) = ROWS(C37:C40), template_label_ok, IF(COUNTIF(C37:C40, "-") = ROWS(C37:C40), "-", template_label_ok))))))))) -> OK
B37: =template_label_type_of_contract_validation -> Type of contract | C37: =IF(COUNTIF('Social Disclosures'!H10, template_label_missing_value) > 0, template_label_missing_value, IF(COUNTIF('Social Disclosures'!H10, template_label_ok) > 0, template_label_ok, "-")) -> OK
B38: =template_label_gender_validation -> Gender | C38: =IF(COUNTIF('Social Disclosures'!H18:H21, template_label_missing_value) > 0, template_label_missing_value, IF(COUNTIF('Social Disclosures'!H18:H21, template_label_ok) > 0, template_label_ok, "-")) -> OK
B39: =template_label_country_of_employment_validation -> Country of employment | C39: =IF(COUNTIF('Social Disclosures'!I29:I38, template_label_missing_value) > 0, template_label_missing_value, IF(COUNTIF('Social Disclosures'!I29:I38, template_label_ok) > 0, template_label_ok, "-")) -> OK
B40: =template_label_turnover_rate_validation -> Turnover rate | C40: =IF(COUNTIF('Social Disclosures'!I44:I46, template_label_missing_value) > 0, template_label_missing_value, IF(COUNTIF('Social Disclosures'!I44:I46, template_label_ok) > 0, template_label_ok, "-")) -> OK
B41: =template_label_b9_workforce_health_and_safety_validation -> · B9 - Workforce – Health and safety | C41: =IF(COUNTIF('Social Disclosures'!I50:I54, template_label_missing_value) > 0, template_label_missing_value, IF(COUNTIF('Social Disclosures'!I50:I54, template_label_ok) > 0, template_label_ok, "-")) -> OK
...

Sheet General Information
A1: =template_label_paragraph_reference -> Paragraph Reference | B1: =template_label_paragraph_guidance_reference -> Paragraph Guidance Reference
C2: =template_label_information_on_the_report_necessary_for_xbrl & " " & template_label_always_to_be_reported -> Information on the report necessary for XBRL [Always to be reported]
C3: =template_label_name_of_the_reporting_entity -> Name of the reporting entity | D3: Company XYZ | F3: =IF(D3 = "", template_label_missing_value, template_label_ok) -> OK
C4: =template_label_identifier_of_the_reporting_entity -> Identifier of the reporting entity (select and specify on the right) | D4: LEI | E4: TestCode1234 | F4: =IF(OR(D4 = "", E4 = ""), template_label_missing_value, template_label_ok) -> OK | G4: =template_label_identifier_warning -> ℹ️ The entity identifier is a unique ID, that will enable identifying the company that has reported the information. The VSME Standard does not require any specific identifier. An entity identifier is required for the digital reporting.
C5: =template_label_currency_of_the_monetary_values_in_the_report -> Currency of the monetary values in the report | D5: EUR | F5: =IF(D5 = "", template_label_missing_value, template_label_ok) -> OK
C6: =template_label_starting_year -> Starting year | D6: 2024 | F6: =IF(OR(D6 = "", D7 = "", D8 = ""), template_label_missing_value, IF(OR( AND(D7 = 2, D8 > 29), AND(D7 = 2, D8 = 29, NOT(AND(MOD(D6, 4) = 0, OR(MOD(D6, 100) <> 0, MOD(D6, 400) = 0)))), AND(OR(D7 = 4, D7 = 6, D7 = 9, D7 = 11), D8 = 31) ), template_label_error, IF(F10 = template_label_value_inconsistency, template_label_value_inconsistency, template_label_ok) ) ) -> OK | G6: =template_label_date_warning -> ℹ️ If VALUE INCONSISTENCY message appears on the right, please ensure that the reporting period end date is greater than the reporting period start date.
C7: =template_label_starting_month -> Starting month | D7: 1
C8: =template_label_starting_day -> Starting day | D8: 1
C9: =template_label_reporting_period_start_date -> Reporting period start date (yyyy-mm-dd) | D9: =IF(OR(ISBLANK(D6), ISBLANK(D7), ISBLANK(D8)), "-", D6 & "-" & TEXT(D7, "00") & "-" & TEXT(D8, "00")) -> 2024-01-01
C10: =template_label_ending_year -> Ending year | D10: 2024 | F10: =IF(OR(D10 = "", D11 = "", D12 = ""), template_label_missing_value, IF(OR( AND(D11 = 2, D12 > 29), AND(D11 = 2, D12 = 29, NOT(AND(MOD(D10, 4) = 0, OR(MOD(D10, 100) <> 0, MOD(D10, 400) = 0)))), AND(OR(D11 = 4, D11 = 6, D11 = 9, D11 = 11), D12 = 31) ), template_label_error, IF(D10 < D6, template_label_value_inconsistency, IF(D10 > D6, template_label_ok, IF(AND(D10 = D6, MATCH(D11, {1;2;3;4;5;6;7;8;9;10;11;12}, 0) < MATCH(D7, {1;2;3;4;5;6;7;8;9;10;11;12}, 0)), template_label_value_inconsistency, IF(AND(D10 = D6, MATCH(D11, {1;2;3;4;5;6;7;8;9;10;11;12}, 0) > MATCH(D7, {1;2;3;4;5;6;7;8;9;10;11;12}, 0)), template_label_ok, IF(AND(D10 = D6, MATCH(D11, {1;2;3;4;5;6;7;8;9;10;11;12}, 0) = MATCH(D7, {1;2;3;4;5;6;7;8;9;10;11;12}, 0), D12 < D8), template_label_value_inconsistency, template_label_ok ))))))) -> OK | G10: =template_label_date_warning -> ℹ️ If VALUE INCONSISTENCY message appears on the right, please ensure that the reporting period end date is greater than the reporting period start date.
C11: =template_label_ending_month -> Ending month | D11: 12
C12: Ending day | D12: 31
C13: =template_label_reporting_period_end_date -> Reporting period end date (yyyy-mm-dd) | D13: =IF(OR(ISBLANK(D10), ISBLANK(D11), ISBLANK(D12)), "-", D10 & "-" & TEXT(D11, "00") & "-" & TEXT(D12, "00")) -> 2024-12-31
C16: =template_label_information_on_previous_reporting_period -> Information on previous reporting period
C17: 16
C18: =template_label_disclosures_from_the_previous_reporting_period_that_remain_unchanged -> This report contains disclosures from the previous reporting period that remain unchanged | E18: TRUE | F18: =IF(E18 = FALSE, "", template_label_ok) -> OK
C19: =template_label_disclosures_for_which_no_changes_are_reported_compared_to_the_previous_period_reporting -> List of disclosures for which no changes are reported compared to the previous period reporting | E19: B2 – Practices, policies and future initiatives for transitioning towards a more sustainable economy | F19: =IF(AND(E18 = FALSE, E19 = ""), "", IF(AND(E18 = FALSE, E19 <> ""), "", IF(AND(E18 = TRUE, E19 = ""), template_label_missing_value, IF(AND(E18 = TRUE, E19 <> "", COUNTIF(E19:E28, E19) = COUNTA(E19:E28), COUNTA(E19:E28) > 1), template_label_value_inconsistency, template_label_ok)))) -> OK | G19: =template_label_additional_rows_warning -> ℹ️ Lists can be expanded using the little [+] button on the left. If the number of rows is not sufficient, those can be added by right clicking the second row and selecting "Insert row".
E20: B3 – Energy and greenhouse gas emissions | F20: =IF($E$18 = FALSE, "", IF(E20 = "", "", IF(COUNTIF($E$19:$E$28, E20) > 1, template_label_value_inconsistency, template_label_ok))) -> OK
F21: =IF($E$18 = FALSE, "", IF(E21 = "", "", IF(COUNTIF($E$19:$E$28, E21) > 1, template_label_value_inconsistency, template_label_ok)))
F22: =IF($E$18 = FALSE, "", IF(E22 = "", "", IF(COUNTIF($E$19:$E$28, E22) > 1, template_label_value_inconsistency, template_label_ok)))
F23: =IF($E$18 = FALSE, "", IF(E23 = "", "", IF(COUNTIF($E$19:$E$28, E23) > 1, template_label_value_inconsistency, template_label_ok)))
F24: =IF($E$18 = FALSE, "", IF(E24 = "", "", IF(COUNTIF($E$19:$E$28, E24) > 1, template_label_value_inconsistency, template_label_ok)))
F25: =IF($E$18 = FALSE, "", IF(E25 = "", "", IF(COUNTIF($E$19:$E$28, E25) > 1, template_label_value_inconsistency, template_label_ok)))
F26: =IF($E$18 = FALSE, "", IF(E26 = "", "", IF(COUNTIF($E$19:$E$28, E26) > 1, template_label_value_inconsistency, template_label_ok)))
F27: =IF($E$18 = FALSE, "", IF(E27 = "", "", IF(COUNTIF($E$19:$E$28, E27) > 1, template_label_value_inconsistency, template_label_ok)))
F28: =IF($E$18 = FALSE, "", IF(E28 = "", "", IF(COUNTIF($E$19:$E$28, E28) > 1, template_label_value_inconsistency, template_label_ok)))
C29: =template_label_link_to_previous_report_containing_disclosures_that_remain_unchanged -> Link to previous report containing disclosures that remain unchanged | E29: www.Test.Report.com | F29: =IF(AND(E18 = FALSE, E29 = ""), "", IF(AND(E18 = TRUE, E29 = ""), template_label_missing_value, IF(AND(E18 = FALSE, E29 <> ""), "", IF(AND(E18 = TRUE, E29 <> "", OR(LEFT(E29, 7) = "http://", LEFT(E29, 8) = "https://", LEFT(E29, 4) = "www.")), template_label_ok, IF(E18 = TRUE, template_label_invalid_url, template_label_missing_value))))) -> OK
C31: =template_label_b1_basis_for_preparation_and_other_undertakings_general_information & " " & template_label_from & " " & template_starting_date_display & " " & template_label_to & " " & template_ending_date_display & " " & template_label_always_to_be_reported -> B1 - Basis for Preparation and other undertaking's general information from 2024-01-01 to 2024-12-31 [Always to be reported]
A32: 24(a) | B32: N/A | C32: =template_label_basis_for_preparation -> Basis for preparation (Basic Module Only or Basic & Comprehensive Module) | E32: Option B (Basic Module and Comprehensive Module) | F32: =IF(E32 = "", template_label_missing_value, template_label_ok) -> OK
A33: 24(b) | B33: N/A | C33: =template_label_list_of_omitted_disclosures_deemed_to_be_classified_or_sensitive_information -> List of omitted disclosures deemed to be classified or sensitive information | E33: None | F33: =IF(E32 = "", "", IF(AND(OR(E32 = "Option A (Basic Module only)", E32 = "Option B (Basic Module and Comprehensive Module)"), E33 = ""), template_label_missing_value, IF(COUNTIF(E33:E42, E33) > 1, template_label_value_inconsistency, template_label_ok))) -> OK
F34: =IF(AND($E$33 = "None", E34 <> ""), template_label_value_inconsistency, IF(E34 = "", "", IF(COUNTIF($E$33:$E$41, E34) > 1, template_label_value_inconsistency, template_label_ok)))
F35: =IF(AND($E$33 = "None", E35 <> ""), template_label_value_inconsistency, IF(E35 = "", "", IF(COUNTIF($E$33:$E$41, E35) > 1, template_label_value_inconsistency, template_label_ok)))
F36: =IF(AND($E$33 = "None", E36 <> ""), template_label_value_inconsistency, IF(E36 = "", "", IF(COUNTIF($E$33:$E$41, E36) > 1, template_label_value_inconsistency, template_label_ok)))
F37: =IF(AND($E$33 = "None", E37 <> ""), template_label_value_inconsistency, IF(E37 = "", "", IF(COUNTIF($E$33:$E$41, E37) > 1, template_label_value_inconsistency, template_label_ok)))
F38: =IF(AND($E$33 = "None", E38 <> ""), template_label_value_inconsistency, IF(E38 = "", "", IF(COUNTIF($E$33:$E$41, E38) > 1, template_label_value_inconsistency, template_label_ok)))
F39: =IF(AND($E$33 = "None", E39 <> ""), template_label_value_inconsistency, IF(E39 = "", "", IF(COUNTIF($E$33:$E$41, E39) > 1, template_label_value_inconsistency, template_label_ok)))
F40: =IF(AND($E$33 = "None", E40 <> ""), template_label_value_inconsistency, IF(E40 = "", "", IF(COUNTIF($E$33:$E$41, E40) > 1, template_label_value_inconsistency, template_label_ok)))
F41: =IF(AND($E$33 = "None", E41 <> ""), template_label_value_inconsistency, IF(E41 = "", "", IF(COUNTIF($E$33:$E$41, E41) > 1, template_label_value_inconsistency, template_label_ok)))
A42: 24(c) | B42: N/A | C42: =template_label_basis_for_reporting -> Basis for reporting (consolidated or individual basis) | E42: Sustainability report prepared on a consolidated basis | F42: =IF(AND(OR(E32 = "Option A (Basic Module only)", E32 = "Option B (Basic Module and Comprehensive Module)"), E42 = ""), template_label_missing_value, IF(E32 = "", "", template_label_ok)) -> OK
A43: 24(e)(i) | B43: 4 | C43: =template_label_undertakings_legal_form -> Undertakings legal form | E43: private limited liability undertaking | F43: =IF(AND(OR(E32 = "Option A (Basic Module only)", E32 = "Option B (Basic Module and Comprehensive Module)"), E43 = ""), template_label_missing_value, IF(E32 = "", "", template_label_ok)) -> OK | G43: =template_label_other_warning -> ℹ️ When "other" is chosen as undertaking legal form please fill the row below
...

Sheet Environmental Disclosures
A1: =template_label_paragraph_reference -> Paragraph Reference | B1: =template_label_paragraph_guidance_reference -> Paragraph Guidance Reference
C2: =template_label_b3_total_energy_consumption&" "&template_label_from&" "&template_starting_date_display&" "&template_label_to&" "&template_ending_date_display&" "&template_label_always_to_be_reported -> B3 - Total Energy Consumption (in MWh) from 2024-01-01 to 2024-12-31 [Always to be reported]
C3: 29
C4: 18-25
C5: =template_label_total_energy_consumption -> Total Energy Consumption | G5: 250 | L5: =IF(AND(OR('General Information'!E32="Option A (Basic Module only)", 'General Information'!E32="Option B (Basic Module and Comprehensive Module)"), G5=""), template_label_missing_value, IF('General Information'!E32="", "", template_label_ok)) -> OK
C7: =template_label_b3_breakdown_of_energy_consumption&" "&template_label_from&" "&template_starting_date_display&" "&template_label_to&" "&template_ending_date_display&" "&template_label_if_applicable -> B3 - Breakdown of energy consumption (in MWh) from 2024-01-01 to 2024-12-31 [If applicable]
C8: 29
C9: 18-25
C10: =template_label_has_the_undertaking_obtained_the_necessary_information_to_provide_an_energy_consumption_breakdown -> Has the undertaking obtained the necessary information to provide an energy consumption breakdown? | G10: TRUE
G11: =template_label_renewable -> Renewable | J11: =template_label_non_renewable -> Non-renewable | K11: =template_label_total_renewable_and_nonrenewable -> Total renewable and non-renewable
C12: =template_label_electricity -> Electricity (as reflected in utility billings) | G12: 10 | J12: 100 | K12: =IF(AND(G12="",J12=""),"-",SUM(G12:J12)) -> 110 | L12: {=IF(G10=TRUE, IF(SUMPRODUCT(--(G12:J14<>"-"), --(G12:J14<>""))>0, IF(SUM(G12:J14) > TotalEnergyConsumption, template_label_value_inconsistency, template_label_ok), template_label_missing_value), "")} -> OK
C13: =template_label_selfgenerated_electricity -> Self-generated electricity | G13: 23 | J13: 20 | K13: =IF(AND(G13="",J13=""),"-",SUM(G13:J13)) -> 43
C14: =template_label_fuels -> Fuels (see Fuel Converter on Fuels worksheet) | G14: =IF('Fuel Converter'!D23=TRUE, 'Fuel Converter'!A32, "-") -> 76.500061 | J14: =IF('Fuel Converter'!D23=TRUE, 'Fuel Converter'!B32, "-") -> 0.00021402795 | K14: =IF(AND(G14="-",J14="-"),"-",SUM(G14:J14)) -> 76.500275 | M14: =template_label_energy_consumption_warning -> ℹ️ Please note that the formula present in this cell may be overwritten in case the undertaking wants to directly provide the value.
C16: =template_label_b3_estimated_greenhouse_gas_emissions& " "&template_label_always_to_be_reported -> B3 - Estimated Greenhouse Gas Emissions considering the GHG Protocol Version 2004 (in tCO2e) [Always to be reported] | G16: =template_label_c3_ghg_reduction_targets&" "&template_label_if_applicable -> C3 - GHG reduction targets (in tC02e) [If applicable]
C17: 30 | G17: 54(b) | J17: 54(a) | K17: 54(d)
C18: N/A | D18: 26-45 | G18: 152-158 | J18: 152-158 | K18: 152-158
G19: =template_label_has_the_undertaking_has_established_ghg_emission_reduction_targets -> Has the undertaking has established GHG emission reduction targets? | J19: TRUE
D20: =template_label_current_reporting_period -> Current Reporting Period | G20: =template_label_base_year -> Base Year | J20: =template_label_target_year -> Target Year | K20: =template_label_percentage_reduction_from_base_year -> Percentage reduction from base year
A21: =template_label_GHG_calculator -> ℹ️ Check EFRAG website for a non-exhaustive list of GHG calculators. | C21: =template_label_year_date -> Year (date) | D21: =IF('General Information'!$D$9="", "-", 'General Information'!$D$9) & " - " & IF('General Information'!$D$13="", "-", 'General Information'!$D$13) -> 2024-01-01 - 2024-12-31 | G21: 2020 | J21: 2030 | L21: =IF(AND(J19=TRUE, G21<>"", J21<>""), template_label_ok, IF(AND(J19=TRUE, G21="", J21=""), template_label_missing_value, IF(AND(J19=FALSE, G21="", J21=""), "", IF(AND(J19=TRUE, OR(G21="", J21="")), template_label_missing_value, "")))) -> OK
C22: =template_label_gross_scope_1_ghg_emissions -> Gross Scope 1 GHG Emissions | D22: 100 | G22: 150 | J22: 75 | K22: =IF(AND(G22="", J22=""), "-", IFERROR(-(1 - (J22 / G22)), "-")) -> -0.5 | L22: =IF(AND(OR(BasisForPreparation="Option A (Basic Module Only)", BasisForPreparation="Option B (Basic Module and Comprehensive Module)"), D22="", J19=FALSE), template_label_missing_value, IF(AND(OR(BasisForPreparation="Option A (Basic Module Only)", BasisForPreparation="Option B (Basic Module and Comprehensive Module)"), D22<>"", G22<>"", J22<>"", J19=TRUE), template_label_ok, IF(AND(BasisForPreparation="Option A (Basic Module Only)", D22<>"", OR(G22="", J22=""), J19=FALSE), template_label_ok, IF(AND(BasisForPreparation="Option A (Basic Module Only)", D22<>"", OR(G22="", J22=""), J19=TRUE), template_label_missing_value, IF(AND(BasisForPreparation="Option B (Basic Module and Comprehensive Module)", D22<>"", OR(G22="", J22=""), J19=TRUE), template_label_missing_value, IF(AND(BasisForPreparation="Option B (Basic Module and Comprehensive Module)", D22="", OR(G22="", J22=""), J19=TRUE), template_label_missing_value, IF(AND(BasisForPreparation="Option A (Basic Module Only)", D22<>"", G22="", J22="", J19=FALSE), template_label_ok, IF(AND(BasisForPreparation="Option B (Basic Module and Comprehensive Module)", D22<>"", G22="", J22="", J19=FALSE), template_label_ok, IF(OR(BasisForPreparation="", D22="", G22="", J22="", J19=FALSE), "", template_label_missing_value))))))))) -> OK
C23: =template_label_gross_scope_2_location_based_ghg_emissions -> Gross Scope 2 location-based GHG Emissions | D23: 50 | G23: 75 | J23: 15 | K23: =IF(AND(G23="", J23=""), "-", IFERROR(-(1 - (J23 / G23)), "-")) -> -0.8 | L23: =IF(AND(OR(BasisForPreparation="Option A (Basic Module Only)", BasisForPreparation="Option B (Basic Module and Comprehensive Module)"), D23="", J19=FALSE), template_label_missing_value, IF(AND(OR(BasisForPreparation="Option A (Basic Module Only)", BasisForPreparation="Option B (Basic Module and Comprehensive Module)"), D23<>"", G23<>"", J23<>"", J19=TRUE), template_label_ok, IF(AND(BasisForPreparation="Option A (Basic Module Only)", D23<>"", OR(G23="", J23=""), J19=FALSE), template_label_ok, IF(AND(BasisForPreparation="Option A (Basic Module Only)", D23<>"", OR(G23="", J23=""), J19=TRUE), template_label_missing_value, IF(AND(BasisForPreparation="Option B (Basic Module and Comprehensive Module)", D23<>"", OR(G23="", J23=""), J19=TRUE), template_label_missing_value, IF(AND(BasisForPreparation="Option B (Basic Module and Comprehensive Module)", D23="", OR(G23="", J23=""), J19=TRUE), template_label_missing_value, IF(AND(BasisForPreparation="Option A (Basic Module Only)", D23<>"", G23="", J23="", J19=FALSE), template_label_ok, IF(AND(BasisForPreparation="Option B (Basic Module and Comprehensive Module)", D23<>"", G23="", J23="", J19=FALSE), template_label_ok, IF(OR(BasisForPreparation="", D23="", G23="", J23="", J19=FALSE), "", template_label_missing_value))))))))) -> OK
C24: =template_label_gross_scope_2_market_based_ghg_emissions & " - " & template_label_may_not_headline -> Gross scope 2 market-based GHG Emissions - May (optional) | K24: =IF(AND(G24="", J24=""), "-", IFERROR(-(1 - (J24 / G24)), "-")) -> - | L24: =IF(D24<>"", IF(AND(G24="", J24=""), template_label_ok, IF(AND(G24<>"", J24=""), template_label_missing_value, template_label_ok) ), "")
C25: =template_label_total_scope_1_and_scope_2_ghg_emissions_location_based -> Total Scope 1 and Scope 2 GHG Emissions (location-based) | D25: =IF(AND(D22="",D23=""),"-",SUM(D22,D23)) -> 150 | G25: =IF(AND(G22="",G23=""),"-",SUM(G22,G23)) -> 225 | J25: =IF(AND(J22="",J23=""),"-",SUM(J22,J23)) -> 90 | K25: =IF(AND(G25="", J25=""), "-", IFERROR(-(1 - (J25 / G25)), "-")) -> -0.6
C26: =template_label_total_scope_1_and_scope_2_ghg_emissions_market_based & " - " & template_label_may_not_headline -> Total Scope 1 and Scope 2 GHG emissions (market-based) - May (optional) | D26: =IF(OR(D22="",D24=""),"-",SUM(D22,D24)) -> - | G26: =IF(OR(G22="",G24=""),"-",SUM(G22,G24)) -> - | J26: =IF(OR(J22="",J24=""),"-",SUM(J22,J24)) -> - | K26: =IF(AND(G26="", J26=""), "-", IFERROR(-(1 - (J26 / G26)), "-")) -> -
C27: 50-53 | G27: 54
C28: N/A | D28: 150-151 | G28: N/A | J28: N/A
C29: =template_label_is_the_undertaking_disclosing_entity_specific_information_on_scope_3_emissions -> Is the undertaking disclosing entity-specific information on Scope 3 emissions (in tCO2e)? | G29: TRUE
C30: =template_label_1_purchased_goods_and_services -> 1. Purchased Goods and Services | D30: 200 | G30: 300 | J30: 100 | K30: =IF(OR(G30="", J30=""), "-", IFERROR(-(1 - (J30 / G30)), "-")) -> -0.66666667 | L30: {=IF( OR( SUMPRODUCT((G30:G44<>"")*(J30:J44="")) > 0, SUMPRODUCT((J30:J44<>"")*(G30:G44="")) > 0 ), template_label_missing_value, IF( AND(G29=TRUE, COUNTA(D30:F44)=0), template_label_missing_value, IF(G29=FALSE, "", template_label_ok) ) )} -> OK | M30: =template_label_scope_3_categories_warning -> ℹ️ Scope 3 categories according to the GHG protocol might help to calculate the total Scope 3 GHG emissions. In case the undertaking wants to, it can directly provide the Total Scope 3 GHG emissions in the respective cell.
C31: =template_label_2_capital_goods -> 2. Capital Goods | K31: =IF(OR(G31="", J31=""), "-", IFERROR(-(1 - (J31 / G31)), "-")) -> -
C32: =template_label_3_fuel__and_energy_related_activities -> 3. Fuel- and Energy-Related Activities (Not Included in Scope 1 or Scope 2) | K32: =IF(OR(G32="", J32=""), "-", IFERROR(-(1 - (J32 / G32)), "-")) -> -
C33: =template_label_4_upstream_transportation_and_distribution -> 4. Upstream Transportation and Distribution | K33: =IF(OR(G33="", J33=""), "-", IFERROR(-(1 - (J33 / G33)), "-")) -> -
C34: =template_label_5_waste_generated_in_operations -> 5. Waste Generated in Operations | K34: =IF(OR(G34="", J34=""), "-", IFERROR(-(1 - (J34 / G34)), "-")) -> -
C35: =template_label_6_business_travel -> 6. Business Travel | K35: =IF(OR(G35="", J35=""), "-", IFERROR(-(1 - (J35 / G35)), "-")) -> -
C36: =template_label_7_employee_commuting -> 7. Employee Commuting | K36: =IF(OR(G36="", J36=""), "-", IFERROR(-(1 - (J36 / G36)), "-")) -> -
C37: =template_label_8_upstream_leased_assets -> 8. Upstream Leased Assets | K37: =IF(OR(G37="", J37=""), "-", IFERROR(-(1 - (J37 / G37)), "-")) -> -
C38: =template_label_9_downstream_transportation_and_distribution -> 9. Downstream Transportation and Distribution | D38: 500 | G38: 400 | J38: 200 | K38: =IF(OR(G38="", J38=""), "-", IFERROR(-(1 - (J38 / G38)), "-")) -> -0.5
C39: =template_label_10_processing_of_sold_products -> 10. Processing of Sold Products | K39: =IF(OR(G39="", J39=""), "-", IFERROR(-(1 - (J39 / G39)), "-")) -> -
C40: =template_label_11_use_of_sold_products -> 11. Use of Sold Products | K40: =IF(OR(G40="", J40=""), "-", IFERROR(-(1 - (J40 / G40)), "-")) -> -
