Workbook
Name AddressOfSite: 'General Information'!$D$404:$D$503
Name AmountOfEmissionsTable: 'Environmental Disclosures'!$D$80:$K$179
Name AmountOfEmissionToAir: 'Environmental Disclosures'!$G$80:$I$179
Name AmountOfEmissionToAir_unit: 'Environmental Disclosures'!$C$78
Name AmountOfEmissionToSoil: 'Environmental Disclosures'!$K$80:$K$179
Name AmountOfEmissionToSoil_unit: 'Environmental Disclosures'!$C$78
Name AmountOfEmissionToWater: 'Environmental Disclosures'!$J$80:$J$179
Name AmountOfEmissionToWater_unit: 'Environmental Disclosures'!$C$78
Name AmountOfWaterWithdrawnAtSitesLocatedInAreasOfHighWaterStress: 'Environmental Disclosures'!$D$304
Name AreaOfSiteInBiodiversitySensitiveArea: 'Environmental Disclosures'!$G$188:$I$287
Name AreaOfSiteInBiodiversitySensitiveArea_unit: 'Environmental Disclosures'!$C$186
Name Assets: 'General Information'!$E$280
Name AverageNumberOfAnnualTrainingHoursPerFemaleEmployee: 'Social Disclosures'!$D$158
Name AverageNumberOfAnnualTrainingHoursPerMaleEmployee: 'Social Disclosures'!$D$157
Name AverageNumberOfAnnualTrainingHoursPerNonReportedGenderEmployee: 'Social Disclosures'!$D$160
Name AverageNumberOfAnnualTrainingHoursPerOtherGenderEmployee: 'Social Disclosures'!$D$159
Name BaselineYearMember: 'Environmental Disclosures'!$G$21
Name BasisForPreparation: 'General Information'!$E$122
Name BasisForReporting: 'General Information'!$E$177
Name BreakdownOfAnnualMassFlowOfRelevantMaterialsUsedByTheUndertakingHypercube: 'Environmental Disclosures'!$C$435:$I$534
Name BreakdownOfEnergyConsumptionAxis: 'Environmental Disclosures'!$C$12:$F$14
Name BreakdownOfEnergyConsumptionTable: 'Environmental Disclosures'!$G$12:$K$14
Name CityOfSite: 'General Information'!$F$404:$F$503
Name CountryOfEmploymentContractAxis: 'Social Disclosures'!$C$29:$D$128
Name CountryOfPrimaryOperationsAndLocationOfSignificantAssets: 'General Information'!$E$285
Name CountryOfSite: 'General Information'!$G$404:$G$503
Name DateOfAdoptionOfTransitionPlanForUndertakingNotHavingAdoptedTransitionPlanYet: 'Environmental Disclosures'!$D$62
Name DescriptionOfActionsTakeToAddressTheConfirmedIncidents: 'Social Disclosures'!$D$192
Name DescriptionOfATargetRelatedToAPolicy: 'General Information'!$E$520
Name DescriptionOfATransitionPlanForClimateChangeMitigationIncludingAnExplanationOfHowItIsContributingToReduceGhgEmissions: 'Environmental Disclosures'!$D$58
Name DescriptionOfClimateRelatedHazardsAndClimateRelatedTransitionEvents: 'Environmental Disclosures'!$E$540
Name DescriptionOfHowCircularEconomyPrinciplesAreApplied: 'Environmental Disclosures'!$D$317
Name DescriptionOfKeyElementsOfStrategyThatRelatesToOrAffectsSustainabilityIssues: 'General Information'!$E$529
Name DescriptionOfLimitsToTheDistributionOfProfitsConnectedToTheMutualisticNatureOrToTheNatureOfTheActivitiesConsistingInServicesOfGeneralEconomicInterestSGEI: 'General Information'!$D$516
Name DescriptionOfMainBusinessRelationships: 'General Information'!$E$527
Name DescriptionOfPracticesPoliciesAndOrFutureInitiatives: 'General Information'!$E$519
Name DescriptionOfSignificantGroupsOfProductsAndOrServicesOffered: 'General Information'!$E$525
Name DescriptionOfSignificantMarketsTheUndertakingOperatesIn: 'General Information'!$E$526
Name DescriptionOfSustainabilityRelatedCertificationsOrLabels: 'General Information'!$E$395
Name DescriptionOfTheEffectiveParticipationOfWorkersUsersOrOtherInterestedPartiesOrCommunitiesInGovernance: 'General Information'!$D$514
Name DisclosureOfAnyOtherEnvironmentalAndOrEntitySpecificEnvironmentalDisclosures: 'Environmental Disclosures'!$C$548
Name DisclosureOfAnyOtherGeneralAndOrEntitySpecificInformation: 'General Information'!$C$533
Name DisclosureOfAnyOtherGovernanceAndOrEntitySpecificGovernanceDisclosures: 'Governance Disclosures'!$C$38
Name DisclosureOfAnyOtherSocialAndOrEntitySpecificSocialDisclosures: 'Social Disclosures'!$C$200
Name DisclosureOfHowItHasAssessedTheExposureAndSensitivityOfItsAssetsActivitiesAndValueChainToTheseHazardsAndTransitionEvents: 'Environmental Disclosures'!$E$541
Name DisclosureOfListOfMainActionsTheEntitySeeksInOrderToAchieveItsTargets: 'Environmental Disclosures'!$C$52
Name DisclosureOfWhetherItHasUndertakenClimateChangeAdaptationActionsForAnyClimateRelatedHazardsAndTransitionEvents: 'Environmental Disclosures'!$E$543
Name EmployeeCountingMethodology: 'General Information'!$E$283
Name EmployeesReceivePayEqualOrAboveMinimumWageDeterminedByNationalLawOrCollectiveAgreement: 'Social Disclosures'!$D$147
Name EmployeeTurnoverRate: 'Social Disclosures'!$D$137
Name EnergyConsumptionFromElectricity_NonRenewableEnergyMember: 'Environmental Disclosures'!$J$12
Name EnergyConsumptionFromElectricity_RenewableEnergyMember: 'Environmental Disclosures'!$G$12
Name EnergyConsumptionFromElectricity_TotalRenewableAndNonRenewableEnergyMember: 'Environmental Disclosures'!$K$12
Name EnergyConsumptionFromFuels_NonRenewableEnergyMember: 'Environmental Disclosures'!$J$14
Name EnergyConsumptionFromFuels_RenewableEnergyMember: 'Environmental Disclosures'!$G$14
Name EnergyConsumptionFromFuels_TotalRenewableAndNonRenewableEnergyMember: 'Environmental Disclosures'!$K$14
Name EnergyConsumptionFromSelfGeneratedElectricity_NonRenewableEnergyMember: 'Environmental Disclosures'!$J$13
Name EnergyConsumptionFromSelfGeneratedElectricity_RenewableEnergyMember: 'Environmental Disclosures'!$G$13
Name EnergyConsumptionFromSelfGeneratedElectricity_TotalRenewableAndNonRenewableEnergyMember: 'Environmental Disclosures'!$K$13
Name enum_B2: 'Enumeration Lists'!$P$2:$P$4

Sheet Language Selection
G5: =template_language_selection -> Language selection
G6: =template_label_select_template_display_language -> VSME Digital Template enable translations into different EU languages. Please select the language from the dropdown below.
G7: English - Official [en] | Q7: ¬

Sheet Introduction
B1: =template_label_version -> Version: | C1: 1.2.0
B2: =template_label_publication_date -> Publication date: | C2: 46080
B3: {=IF(ISERROR(CELL("filename",A1)),template_label_warning_microsoft_excel,"")}
B10: =template_label_taxonomy_entry_point -> Taxonomy entry point: | C10: https://xbrl.efrag.org/taxonomy/vsme/2026-02-01/vsme-all.xsd
B11: =template_label_title_of_report -> Main title of the report | C11: =template_label_main_title_of_report_text -> Sustainability Report
B12: =template_label_subtitle_of_report -> Subtitle of the report | C12: =template_label_subtitle_of_report_text -> Prepared in accordance with the Voluntary Sustainability Reporting Standard for small and medium-sized undertakings (VSME), released by the European Commission on 30 July 2025.
B13: =template_label_vsme_digital_template -> VSME Digital Template
B14: =template_label_the_purpose_of_this_digital_template_is_to_illustrate_how_vsme_reporting_can_be_implemented_in_a_digital_template -> The purpose of this digital template is to illustrate how VSME reporting can be implemented in a digital template. The template reflects the VSME Recommendation as published by the European Commission on 30 July 2025. The template is accompanied by a digital VSME XBRL taxonomy, which represents the digital data model of the disclosures and is available on EFRAG's website. The VSME requires disclosure of comparative information on metrics (paragraph 12). This template enables reporting for one reporting period only. Therefore, it might be used for reporting in the first year only. It is expected that reporting solutions will enable the roll-forward of reporting periods, which would automatically provide the necessary comparative information. This template can be used for data entry and validation. By using an XBRL Converter on EFRAG's website, it can be saved as an XBRL report, in a free and open data format. Excel-named ranges are used to extract the disclosures. Value cells that are empty and do not have any value (neither text nor a number) will not be considered as reported and will not be included in the XBRL report when using the Excel-to-XBRL converter. A few drop-down selection menus in the VSME have more than 100 entries (e.g. the NACE codes under B1, the list of pollutants under B4, the list of wastes under B7). In order to search in the list, users can simply start typing search keywords in the cell. If a security warning is shown, please "Enable Content" in order to allow automatic calculation of GPS coordinates for the list of sites under B1. No content other than the address entered will be sent to the internet and the contents shared with the provider can be found in the Nominatim Usage Policy (Geocoding Policy) and Privacy Policy. All materials developed by the EFRAG Secretariat are released for free and as open source (MIT license), which will enable any stakeholder to further enhance them and integrate them into commercial solutions. However, respecting the license conditions, the reference to EFRAG must be mentioned by the providers of those commercial solutions. It's possible to consult the MIT License in the specific sheet. If you wish to raise an issue with the VSME Digital Template or the Digital Template to XBRL Converter, please do so by creating an issue in the GitHub project.
B17: =template_label_how_to_use_it -> How to use it:
B18: =template_label_0_provide_information_that_is_mandatory_in_order_to_generate_the_vsme_and_xbrl_report -> 0. Provide information that is mandatory in order to generate the VSME and XBRL Report.
B19: =template_label_1_fill_in_the_disclosures_on_the_four_worksheets -> 1. Fill in the disclosures on the four worksheets (General Information, Environmental Disclosures, Social Disclosures, Governance Disclosures) in the white cells framed by a black border. Do not enter information outside of those cells. Searching in drop-downs can be done by typing into the cell. Hints (input messages) are shown in several cells when selecting them.
B20: =template_label_2_find_more_information_on_the_actual_disclosure_requirements_in_the_vsme_standard -> 2. Find more information on the actual disclosure requirements in the VSME Standard and the related guidance linked to each cell. Additional or entity-specific disclosures can be provided in each text box at the end of each worksheet.
B21: =template_label_3_for_open_tables_like_the_list_of_subsidizers_sites_please_expand_the_groups_by_clicking_the_plus -> 3. For open tables like the List of subsidiaries/sites, please expand the groups by clicking the plus [+] icon on the left side. If more rows are needed, they can be added by inserting them between the first and last row. The row IDs in open tables must remain unique per table.
B22: =template_label_4_validate_the_data_entered_by_checking_the_validation_status -> 4. Validate the data entered by checking the validation status. The report is considered incomplete or erroneous if the validation fails, which might result in an invalid XBRL report.
B23: =template_label_5_convert_this_template_to_an_inline_xbrl_report -> 5. Convert this template to an Inline XBRL report (or XBRL-JSON, XBRL-CSV), using the online converter: https://xbrl.efrag.org/convert/. Pay attention to the XBRL validation performed by the validator.
B24: =template_label_6_the_undertaking_may_also_upload_the_report_to_public_repositories_or_a_webpage -> 6. The undertaking may also upload the report to public repositories or a webpage.
B26: =template_label_cell_background_color_index -> Cell background color index:
B27: =template_label_general_principles -> General Principles | C27: =template_label_indicates_that_the_disclosure_is_from_the_general_principles_of_the_vsme -> Indicates that the disclosure is from the general principles of the VSME.
B28: =template_label_basic_module -> Basic Module | C28: =template_label_indicates_that_the_disclosure_is_from_the_vsme_basic_module -> Indicates that the disclosure is from the VSME Basic Module.
B29: =template_label_comprehensive_module -> Comprehensive Module | C29: =template_label_indicates_that_the_disclosure_is_from_the_vsme_comprehensive_module -> Indicates that the disclosure is from the VSME Comprehensive Module.
C30: =template_label_indicates_that_the_cell_is_automatically_calculated_and_that_no_data_entry_is_required -> Indicates that the cell is automatically calculated and that no data entry is required.
C31: =template_label_indicates_that_the_datapoint_often_a_condition_will_not_be_included_in_the_vsme_and_digital_xbrl_report -> Indicates that the datapoint (often a condition) will not be included in the VSME and digital XBRL report. These cells are provided to facilitate the completion of the disclosure as they either trigger the applicability of the disclosure or they enable the automatic calculation of the disclosure. If the yellow cells are not being used to calculate a value, the total that is to be reported can be entered manually overwriting by the formula.
C32: =template_label_indicates_that_no_data_entry_is_required_unless_certain_logics_are_selected_in_the_disclosure_itself -> Indicates that no data entry is required unless certain logics are selected in the disclosure itself. When one of these logics is selected, then this cell will turn white.
B33: =template_label_validation_missing_value_error_velue_inconsistency_invalid_url -> Validation MISSING VALUE/ERROR/VALUE INCONSISTENCY/INVALID URL | C33: =template_label_indicates_that_either_data_entry_is_incorrect_in_terms_of_format_or_that_certain_information -> Indicates that either data entry is incorrect in terms of format or that certain information is missing in order to correctly report on the disclosure.
B34: Validation OK | C34: =template_label_indicates_that_data_entry_is_ok_and_the_undertaking_can_proceed_to_the_next_disclosure -> Indicates that data entry is OK and the undertaking can proceed to the next disclosure.
B35: =template_label_validation_classified_or_sensitive_information -> Validation CLASSIFIED OR SENSITIVE INFORMATION | C35: =template_label_indicates_that_the_undertaking_has_omitted_the_data_entry_as_it_is_deemed_to_be_classified_or_sensitive_information -> Indicates that the undertaking has omitted the data entry as it is deemed to be classified or sensitive information.
C36: =template_label_no_value_can_be_entered_in_the_cell -> No value can be entered in the cell.
B37: [+] | C37: =template_label_lists_can_be_expanded_using_the_plus_button_on_the_left -> Lists can be expanded using the plus [+] button on the left. If the number of rows is not sufficient, additional rows can be added by right clicking the second row and selecting "Insert row".
B43: =template_label_efrag_is_funded_by_the_european_union_through_the_single_market_programme -> EFRAG is funded by the European Union through the Single Market Programme in which the EEA-EFTA countries (Norway, Iceland and Liechtenstein), as well as Kosovo participate. Any views and opinions expressed are however those of the author(s) only and do not necessarily reflect those of the European Union, the European Commission or of countries that participate in the Single Market Programme. Neither the European Union, the European Commission nor countries participating in the Single market Programme can be held responsible for them. © 2025 EFRAG All rights reserved.
B44: =template_label_reproduction_and_use_rights_are_strictly_limited -> Reproduction and use rights are strictly limited. For further details please contact efragsecretariat@efrag.org

Sheet Table of Contents & Validation
B2: =template_label_table_of_contents_validation -> Table of Contents | C2: =template_label_overall_validation_status_validation -> Overall Validation Status | D2: =template_classified_or_sensitive_information -> Classified or sensitive information
B3: =template_label_contents_grouping_follows_templates_framework -> Contents grouping follows template's framework | C3: {=IF(SUMPRODUCT(--((C5:C70<>template_label_ok)*(C5:C70<>"-")*(C5:C70<>"")*(C5:C70<>template_label_classified_or_sensitive_information))) > 0, template_label_incomplete, template_label_complete)} -> INCOMPLETE | D3: =template_filling_sensitive_checkboxes -> Filling the checkboxes below will fill automatically the list of omitted disclosures in B1 (from row 123 to 172 within General Information sheet)
C4: =template_label_specific_content_validation_status_validation -> Specific Content Validation Status
B5: =template_label_general_information_validation -> General Information
B6: =template_label_information_on_the_report_necessary_for_xbrl_validation -> Information on the report necessary for XBRL | C6: =IF( AND( COUNTIF('General Information'!F3:F12, template_label_missing_value) > 0, COUNTIF('General Information'!F3:F12, template_label_error) = 0 ), template_label_missing_value, IF( AND( COUNTIF('General Information'!F3:F12, template_label_error) > 0, COUNTIF('General Information'!F3:F12, template_label_missing_value) = 0 ), template_label_value_inconsistency, IF( AND( COUNTIF('General Information'!F3:F12, template_label_error) > 0, COUNTIF('General Information'!F3:F12, template_label_missing_value) > 0 ), template_label_error_plus_value_inconsistency, template_label_ok ) ) ) -> MISSING VALUE
B7: =template_label_information_on_previous_reporting_period_validation -> Information on previous reporting period | C7: =IF(COUNTIF('General Information'!F18:F119, template_label_missing_value) > 0, template_label_missing_value, IF(COUNTIF('General Information'!F18:F119, template_label_invalid_url ) > 0, template_label_invalid_url, IF(COUNTIF('General Information'!F18:F119, template_label_value_inconsistency ) > 0, template_label_value_inconsistency, IF(COUNTIF('General Information'!F18:F119, template_label_ok) > 0, template_label_ok, "-")))) -> -
B8: =template_label_basic_module_validation -> Basic Module
B9: =template_label_general_information_validation -> General Information
B10: =template_label_b1_basis_for_preparation_validation -> B1 - Basis for Preparation | C10: =IF(D10=TRUE,template_label_classified_or_sensitive_information, IF(COUNTIF(C11:C15,template_label_error_plus_missing_value_plus_value_inconsistency)>0,template_label_error_plus_missing_value_plus_value_inconsistency, IF(COUNTIF(C11:C15,template_label_error_plus_value_inconsistency)>0,template_label_error_plus_value_inconsistency, IF(COUNTIF(C11:C15,template_label_error_plus_missing_value)>0,template_label_error_plus_missing_value, IF(COUNTIF(C11:C15,template_label_error)>0,template_label_error, IF(COUNTIF(C11:C15,template_label_missing_value_plus_value_inconsistency)>0,template_label_missing_value_plus_value_inconsistency, IF(COUNTIF(C11:C15,template_label_value_inconsistency)>0,template_label_value_inconsistency, IF(COUNTIF(C11:C15,template_label_missing_value)>0,template_label_missing_value, IF(COUNTIF(C11:C15,template_label_ok)=ROWS(C11:C15),template_label_ok, IF(COUNTIF(C11:C15,"-")=ROWS(C11:C15),"-", IF(AND(COUNTIF(C11:C15,template_label_ok)>0, COUNTIF(C11:C15,template_label_error_plus_missing_value_plus_value_inconsistency)=0, COUNTIF(C11:C15,template_label_error_plus_value_inconsistency)=0, COUNTIF(C11:C15,template_label_error_plus_missing_value)=0, COUNTIF(C11:C15,template_label_error)=0, COUNTIF(C11:C15,template_label_missing_value_plus_value_inconsistency)=0, COUNTIF(C11:C15,template_label_value_inconsistency)=0, COUNTIF(C11:C15,template_label_missing_value)=0, OR(COUNTIF(C11:C15,template_label_missing_value)=0, COUNTIF(C11:C15,template_label_missing_value)>0)), template_label_ok, "-"))))))))) )) -> MISSING VALUE | D10: =IF(COUNTIF(D12:D15,TRUE)=ROWS(D12:D15),TRUE,FALSE) -> FALSE
B11: =template_label_b1_basis_for_preparation -> B1 - Basis for Preparation & Module | C11: =IF(COUNTIF('General Information'!F122,template_label_missing_value)>0,template_label_missing_value, IF(COUNTIF('General Information'!F122,template_label_ok)>0,template_label_ok,"-")) -> MISSING VALUE
B12: =template_label_b1_other_undertakings_general_information -> B1 - Other undertaking's general information | C12: =IF(D12=TRUE, template_label_classified_or_sensitive_information,IF( AND( COUNTIF('General Information'!F177:F285,template_label_missing_value)>0, COUNTIF('General Information'!F177:F285,template_label_value_inconsistency)=0, COUNTIF('General Information'!F177:F285,template_label_error)=0 ), template_label_missing_value, IF( AND( COUNTIF('General Information'!F177:F285,template_label_value_inconsistency)>0, COUNTIF('General Information'!F177:F285,template_label_missing_value)=0, COUNTIF('General Information'!F177:F285,template_label_error)=0 ), template_label_value_inconsistency, IF( AND( COUNTIF('General Information'!F177:F285,template_label_value_inconsistency)=0, COUNTIF('General Information'!F177:F285,template_label_missing_value)=0, COUNTIF('General Information'!F177:F285,template_label_error)>0 ), template_label_error, IF( AND( COUNTIF('General Information'!F177:F285,template_label_value_inconsistency)>0, COUNTIF('General Information'!F177:F285,template_label_missing_value)>0, COUNTIF('General Information'!F177:F285,template_label_error)=0 ), template_label_missing_value_plus_value_inconsistency, IF( AND( COUNTIF('General Information'!F177:F285,template_label_value_inconsistency)=0, COUNTIF('General Information'!F177:F285,template_label_missing_value)>0, COUNTIF('General Information'!F177:F285,template_label_error)>0 ), template_label_error_plus_missing_value, IF( AND( COUNTIF('General Information'!F177:F285,template_label_value_inconsistency)>0, COUNTIF('General Information'!F177:F285,template_label_missing_value)=0, COUNTIF('General Information'!F177:F285,template_label_error)>0 ), template_label_error_plus_value_inconsistency, IF( AND( COUNTIF('General Information'!F177:F285,template_label_value_inconsistency)>0, COUNTIF('General Information'!F177:F285,template_label_missing_value)>0, COUNTIF('General Information'!F177:F285,template_label_error)>0 ), template_label_error_plus_missing_value_plus_value_inconsistency, IF( AND( COUNTIF('General Information'!F177:F285,template_label_value_inconsistency)=0, COUNTIF('General Information'!F177:F285,template_label_missing_value)=0, COUNTIF('General Information'!F177:F285,template_label_error)=0, COUNTIF('General Information'!F177:F285,template_label_ok)>0 ), template_label_ok, "-" ))))))))) -> - | D12: FALSE | E12: =IF(AND(C12=template_label_classified_or_sensitive_information,COUNTIF('General Information'!E177:E285,"<>")>0),template_label_information_on_sensitive_information_before_converting,"")
B13: =template_label_b1_list_of_subsidiaries -> B1 - List of subsidiaries | C13: =IF(D13=TRUE, template_label_classified_or_sensitive_information, IF( COUNTIF('General Information'!F290:F389, template_label_missing_value) > 0, template_label_missing_value, IF( COUNTIF('General Information'!F290:F389, template_label_ok) > 0, template_label_ok, "-" ) ) ) -> - | D13: FALSE | E13: =IF(AND(C13=template_label_classified_or_sensitive_information,COUNTIF('General Information'!D404:G503,"<>")>0),template_label_information_on_sensitive_information_before_converting,"")
B14: =template_label_b1_disclosure_of_sustainability_related_certification_or_label -> B1 - Disclosure of sustainability-related certification(s) or label(s) | C14: =IF(D14=TRUE, template_label_classified_or_sensitive_information, IF( COUNTIF('General Information'!I395, template_label_missing_value) > 0, template_label_missing_value, IF( COUNTIF('General Information'!I395, template_label_ok) > 0, template_label_ok, "-" ) ) ) -> - | D14: FALSE | E14: =IF(AND(C14=template_label_classified_or_sensitive_information,'General Information'!E394=TRUE),template_label_information_on_sensitive_information_before_converting,"")
B15: =template_label_b1_list_of_site -> B1 - List of site(s) | C15: =IF(D15=TRUE, template_label_classified_or_sensitive_information, IF( COUNTIF('General Information'!I404:I503, template_label_missing_value) > 0, template_label_missing_value, IF( COUNTIF('General Information'!I404:I503, template_label_ok) > 0, template_label_ok, "-" ) ) ) -> - | D15: FALSE | E15: =IF(AND(C15=template_label_classified_or_sensitive_information,COUNTIF('General Information'!D404:G503,"<>")>0),template_label_information_on_sensitive_information_before_converting,"")
B16: =template_label_b2_practices_policies_and_future_initiatives_for_transitioning_towards_a_more_sustainable_economy -> B2 - Practices, policies and future initiatives for transitioning towards a more sustainable economy | C16: =IF(D16=TRUE, template_label_classified_or_sensitive_information, IF( COUNTIF('General Information'!P510, template_label_missing_value) > 0, template_label_missing_value, IF( COUNTIF('General Information'!P510, template_label_ok) > 0, template_label_ok, "-" ) ) ) -> - | D16: FALSE | E16: =IF(AND(C16=template_label_classified_or_sensitive_information,'General Information'!C510=TRUE),template_label_information_on_sensitive_information_before_converting,"")
B17: =template_label_b2_cooperative_specific_disclosures -> B2 - Cooperative specific disclosures | C17: {=IF(D17=TRUE, template_label_classified_or_sensitive_information, IF(OR('General Information'!E514:E516=template_label_ok),template_label_ok,"-") )} -> - | D17: FALSE | E17: =IF(AND(C17=template_label_classified_or_sensitive_information,COUNTIF('General Information'!D514:D516,"<>")>0),template_label_information_on_sensitive_information_before_converting,"")
B18: =template_label_environmental_disclosures_validation -> Environmental Disclosures
B19: =template_label_b3_energy_and_greenhouse_gas_emissions_validation -> B3 - Energy and greenhouse gas emissions | C19: =IF(D19=TRUE,template_label_classified_or_sensitive_information, IF(COUNTIF(C20:C23,template_label_error_plus_missing_value_plus_value_inconsistency)>0,template_label_error_plus_missing_value_plus_value_inconsistency, IF(COUNTIF(C20:C23,template_label_error_plus_value_inconsistency)>0,template_label_error_plus_value_inconsistency, IF(COUNTIF(C20:C23,template_label_error_plus_missing_value)>0,template_label_error_plus_missing_value, IF(COUNTIF(C20:C23,template_label_error)>0,template_label_error, IF(COUNTIF(C20:C23,template_label_missing_value_plus_value_inconsistency)>0,template_label_missing_value_plus_value_inconsistency, IF(COUNTIF(C20:C23,template_label_value_inconsistency)>0,template_label_value_inconsistency, IF(COUNTIF(C20:C23,template_label_missing_value)>0,template_label_missing_value, IF(COUNTIF(C20:C23,template_label_ok)=ROWS(C20:C23),template_label_ok, IF(COUNTIF(C20:C23,"-")=ROWS(C20:C23),"-", IF(AND(COUNTIF(C20:C23,template_label_ok)>0, COUNTIF(C20:C23,template_label_error_plus_missing_value_plus_value_inconsistency)=0, COUNTIF(C20:C23,template_label_error_plus_value_inconsistency)=0, COUNTIF(C20:C23,template_label_error_plus_missing_value)=0, COUNTIF(C20:C23,template_label_error)=0, COUNTIF(C20:C23,template_label_missing_value_plus_value_inconsistency)=0, COUNTIF(C20:C23,template_label_value_inconsistency)=0, COUNTIF(C20:C23,template_label_missing_value)=0,OR(COUNTIF(C20:C23,template_label_missing_value)=0, COUNTIF(C20:C23,template_label_missing_value)>0)), template_label_ok, "-"))))))))) )) -> - | D19: =IF(COUNTIF(D20:D23,TRUE)=ROWS(D20:D23),TRUE,FALSE) -> FALSE
B20: =template_label_b3_total_energy_consumption -> B3 - Total Energy Consumption (in MWh) | C20: =IF(D20=TRUE, template_label_classified_or_sensitive_information, IF(COUNTIF('Environmental Disclosures'!L5,template_label_missing_value)>0,template_label_missing_value, IF(COUNTIF('Environmental Disclosures'!L5,template_label_ok)>0,template_label_ok,"-")) ) -> - | D20: FALSE | E20: =IF(AND(C20=template_label_classified_or_sensitive_information,COUNTIF(TotalEnergyConsumption,"<>")>0),template_label_information_on_sensitive_information_before_converting,"")
B21: =template_label_b3_breakdown_of_energy_consumption -> B3 - Breakdown of energy consumption (in MWh) | C21: =IF(D21=TRUE,template_label_classified_or_sensitive_information, IF( AND( COUNTIF('Environmental Disclosures'!L12:L14,template_label_missing_value)>0, COUNTIF('Environmental Disclosures'!L12:L14,template_label_value_inconsistency)=0 ), template_label_missing_value, IF( AND( COUNTIF('Environmental Disclosures'!L12:L14,template_label_value_inconsistency)>0, COUNTIF('Environmental Disclosures'!L12:L14,template_label_missing_value)=0 ), template_label_value_inconsistency, IF( AND( COUNTIF('Environmental Disclosures'!L12:L14,template_label_value_inconsistency)>0, COUNTIF('Environmental Disclosures'!L12:L14,template_label_missing_value)>0 ), template_label_error_plus_value_inconsistency, IF( COUNTIF('Environmental Disclosures'!L12:L14,"-")=3, "-", IF( COUNTIF('Environmental Disclosures'!L12:L14,template_label_ok)>0, template_label_ok, "-" ) )) )) ) -> - | D21: FALSE | E21: =IF(AND(C21=template_label_classified_or_sensitive_information,'Environmental Disclosures'!G10=TRUE),template_label_information_on_sensitive_information_before_converting,"")
B22: =template_label_b3_estimated_greenhouse_gas_emissions -> B3 - Estimated Greenhouse Gas Emissions considering the GHG Protocol Version 2004 (in tCO2e) | C22: =IF(D22=TRUE, template_label_classified_or_sensitive_information, IF(COUNTIF('Environmental Disclosures'!L21:L44,template_label_missing_value)>0,template_label_missing_value, IF(COUNTIF('Environmental Disclosures'!L21:L44,template_label_ok)>0,template_label_ok,"-")) ) -> - | D22: FALSE | E22: =IF(AND(C22=template_label_classified_or_sensitive_information,COUNTIF('Environmental Disclosures'!D22:F24,"<>")>0),template_label_information_on_sensitive_information_before_converting,"")
B23: =template_label_b3_greenhouse_gas_emission_intensity_per_turnover -> B3 - Greenhouse gas emission intensity per turnover (in tCO2e) | C23: =IF(D23=TRUE, template_label_classified_or_sensitive_information, IF(C22=template_label_ok,template_label_ok,"-") ) -> - | D23: FALSE | E23: =IF(AND(C23=template_label_classified_or_sensitive_information,COUNTIF('Environmental Disclosures'!D22:F24,"<>")>0,COUNTIF(Turnover,"<>")>0),template_label_information_on_sensitive_information_before_converting,"")
B24: =template_label_b4_pollution_of_air_water_and_soil_validation -> B4 - Pollution of air, water and soil | C24: =IF(D24=TRUE, template_label_classified_or_sensitive_information, IF(COUNTIF('Environmental Disclosures'!L75:L179,template_label_invalid_url)>0, template_label_invalid_url, IF(AND(COUNTIF('Environmental Disclosures'!L75:L179,template_label_missing_value)>0, COUNTIF('Environmental Disclosures'!L75:L179,template_label_value_inconsistency)>0), template_label_missing_value_plus_value_inconsistency, IF(COUNTIF('Environmental Disclosures'!L75:L179,template_label_missing_value)>0, template_label_missing_value, IF(COUNTIF('Environmental Disclosures'!L75:L179,template_label_value_inconsistency)>0, template_label_value_inconsistency, IF(COUNTIF('Environmental Disclosures'!L75:L179,template_label_ok)>0, template_label_ok, "-"))))) ) -> - | D24: FALSE | E24: =IF(AND(C24=template_label_classified_or_sensitive_information,'Environmental Disclosures'!G74=TRUE),template_label_information_on_sensitive_information_before_converting,"")
B25: =template_label_b5_biodiversity_validation -> B5 - Biodiversity | C25: =IF(D25=TRUE, template_label_classified_or_sensitive_information, IF(COUNTIF(C26:C27,template_label_error_plus_missing_value_plus_value_inconsistency)>0,template_label_error_plus_missing_value_plus_value_inconsistency, IF(COUNTIF(C26:C27,template_label_error_plus_value_inconsistency)>0,template_label_error_plus_value_inconsistency, IF(COUNTIF(C26:C27,template_label_error_plus_missing_value)>0,template_label_error_plus_missing_value, IF(COUNTIF(C26:C27,template_label_error)>0,template_label_error, IF(COUNTIF(C26:C27,template_label_missing_value_plus_value_inconsistency)>0,template_label_missing_value_plus_value_inconsistency, IF(COUNTIF(C26:C27,template_label_value_inconsistency)>0,template_label_value_inconsistency, IF(COUNTIF(C26:C27,template_label_missing_value)>0,template_label_missing_value, IF(COUNTIF(C26:C27,template_label_ok)=ROWS(C26:C27),template_label_ok, IF(COUNTIF(C26:C27,"-")=ROWS(C26:C27),"-", IF(AND(COUNTIF(C26:C27,template_label_ok)>0, COUNTIF(C26:C27,template_label_error_plus_missing_value_plus_value_inconsistency)=0, COUNTIF(C26:C27,template_label_error_plus_value_inconsistency)=0, COUNTIF(C26:C27,template_label_error_plus_missing_value)=0, COUNTIF(C26:C27,template_label_error)=0, COUNTIF(C26:C27,template_label_missing_value_plus_value_inconsistency)=0, COUNTIF(C26:C27,template_label_value_inconsistency)=0, COUNTIF(C26:C27,template_label_missing_value)=0,OR(COUNTIF(C26:C27,template_label_missing_value)=0, COUNTIF(C26:C27,template_label_missing_value)>0)), template_label_ok, "-"))))))))) )) -> - | D25: =IF(COUNTIF(D26:D27,TRUE)=ROWS(D26:D27),TRUE,FALSE) -> FALSE
B26: =template_label_b5_sites_in_biodiversity_sensitive_areas -> B5 - Sites in biodiversity sensitive areas | C26: =IF(D26=TRUE, template_label_classified_or_sensitive_information, IF(AND( COUNTIF('Environmental Disclosures'!D188:D287,template_label_ok) + COUNTIF('Environmental Disclosures'!L186:L287,template_label_ok) > 0, COUNTIF('Environmental Disclosures'!D188:D287,template_label_missing_value) + COUNTIF('Environmental Disclosures'!L186:L287,template_label_missing_value) = 0, COUNTIF('Environmental Disclosures'!D188:D287,template_label_value_inconsistency) + COUNTIF('Environmental Disclosures'!L186:L287,template_label_value_inconsistency) = 0), template_label_ok, IF(AND( COUNTIF('Environmental Disclosures'!D188:D287,template_label_missing_value) + COUNTIF('Environmental Disclosures'!L186:L287,template_label_missing_value) > 0, COUNTIF('Environmental Disclosures'!D188:D287,template_label_value_inconsistency) + COUNTIF('Environmental Disclosures'!L186:L287,template_label_value_inconsistency) = 0), template_label_missing_value, IF(AND( COUNTIF('Environmental Disclosures'!D188:D287,template_label_value_inconsistency) + COUNTIF('Environmental Disclosures'!L186:L287,template_label_value_inconsistency) > 0, COUNTIF('Environmental Disclosures'!D188:D287,template_label_missing_value) + COUNTIF('Environmental Disclosures'!L186:L287,template_label_missing_value) = 0), template_label_value_inconsistency, IF(AND( COUNTIF('Environmental Disclosures'!D188:D287,template_label_value_inconsistency) + COUNTIF('Environmental Disclosures'!L186:L287,template_label_value_inconsistency) > 0, COUNTIF('Environmental Disclosures'!D188:D287,template_label_missing_value) + COUNTIF('Environmental Disclosures'!L186:L287,template_label_missing_value) > 0), template_label_missing_value_plus_value_inconsistency, "-" ) ) ) ) ) -> - | D26: FALSE | E26: =IF(AND(C26=template_label_classified_or_sensitive_information,'Environmental Disclosures'!G184=TRUE),template_label_information_on_sensitive_information_before_converting,"")
B27: =template_label_b5_biodiversity_land_use -> B5 - Biodiversity - Land-use | C27: =IF(D27=TRUE, template_label_classified_or_sensitive_information, IF( AND( COUNTIF('Environmental Disclosures'!G293:G298,template_label_missing_value)>0, COUNTIF('Environmental Disclosures'!G293:G298,template_label_value_inconsistency)=0, COUNTIF('Environmental Disclosures'!G293:G298,template_label_ok)>=0 ), template_label_missing_value, IF( AND( COUNTIF('Environmental Disclosures'!G293:G298,template_label_value_inconsistency)>0, COUNTIF('Environmental Disclosures'!G293:G298,template_label_missing_value)=0, COUNTIF('Environmental Disclosures'!G293:G298,template_label_ok)>=0 ), template_label_value_inconsistency, IF( AND( COUNTIF('Environmental Disclosures'!G293:G298,template_label_value_inconsistency)>0, COUNTIF('Environmental Disclosures'!G293:G298,template_label_missing_value)>0, COUNTIF('Environmental Disclosures'!G293:G298,template_label_ok)>=0 ), template_label_missing_value_plus_value_inconsistency, IF( AND( COUNTIF('Environmental Disclosures'!G293:G298,template_label_value_inconsistency)=0, COUNTIF('Environmental Disclosures'!G293:G298,template_label_missing_value)=0, COUNTIF('Environmental Disclosures'!G293:G298,template_label_ok)>0 ), template_label_ok, "-" ) ) )) ) -> - | D27: FALSE | E27: =IF(AND(C27=template_label_classified_or_sensitive_information,COUNTIF('Environmental Disclosures'!D295:F298,"<>")>0),template_label_information_on_sensitive_information_before_converting,"")
B28: =template_label_b6_water_validation -> B6 - Water | C28: =IF(D28=TRUE, template_label_classified_or_sensitive_information, IF(COUNTIF(C29:C30,template_label_error_plus_missing_value_plus_value_inconsistency)>0,template_label_error_plus_missing_value_plus_value_inconsistency, IF(COUNTIF(C29:C30,template_label_error_plus_value_inconsistency)>0,template_label_error_plus_value_inconsistency, IF(COUNTIF(C29:C30,template_label_error_plus_missing_value)>0,template_label_error_plus_missing_value, IF(COUNTIF(C29:C30,template_label_error)>0,template_label_error, IF(COUNTIF(C29:C30,template_label_missing_value_plus_value_inconsistency)>0,template_label_missing_value_plus_value_inconsistency, IF(COUNTIF(C29:C30,template_label_value_inconsistency)>0,template_label_value_inconsistency, IF(COUNTIF(C29:C30,template_label_missing_value)>0,template_label_missing_value, IF(COUNTIF(C29:C30,template_label_ok)=ROWS(C29:C30),template_label_ok, IF(COUNTIF(C29:C30,"-")=ROWS(C29:C30),"-", IF(AND(COUNTIF(C29:C30,template_label_ok)>0, COUNTIF(C26:C27,template_label_error_plus_missing_value_plus_value_inconsistency)=0, COUNTIF(C29:C30,template_label_error_plus_value_inconsistency)=0, COUNTIF(C29:C30,template_label_error_plus_missing_value)=0, COUNTIF(C29:C30,template_label_error)=0, COUNTIF(C29:C30,template_label_missing_value_plus_value_inconsistency)=0, COUNTIF(C29:C30,template_label_value_inconsistency)=0, COUNTIF(C29:C30,template_label_missing_value)=0,OR(COUNTIF(C29:C30,template_label_missing_value)=0, COUNTIF(C29:C30,template_label_missing_value)>0)), template_label_ok, "-"))))))))) )) -> - | D28: =IF(COUNTIF(D29:D30,TRUE)=ROWS(D29:D30),TRUE,FALSE) -> FALSE
B29: =template_label_b6_water_withdrawal -> B6 - Water Withdrawal | C29: =IF(D29=TRUE, template_label_classified_or_sensitive_information, IF(COUNTIF('Environmental Disclosures'!E303:F304, template_label_missing_value) > 0, template_label_missing_value, IF(COUNTIF('Environmental Disclosures'!E303:F304, template_label_ok) > 0, template_label_ok, "-")) ) -> - | D29: FALSE | E29: =IF(AND(C29=template_label_classified_or_sensitive_information,COUNTIF('Environmental Disclosures'!D303:D304,"<>")>0),template_label_information_on_sensitive_information_before_converting,"")
B30: =template_label_b6_water_consumption -> B6 - Water Consumption | C30: =IF(D30=TRUE, template_label_classified_or_sensitive_information, IF(COUNTIF('Environmental Disclosures'!E310:F310, template_label_missing_value) > 0, template_label_missing_value, IF(COUNTIF('Environmental Disclosures'!E310:F310, template_label_ok) > 0, template_label_ok, "-")) ) -> - | D30: FALSE | E30: =IF(AND(C30=template_label_classified_or_sensitive_information,'Environmental Disclosures'!D309=TRUE),template_label_information_on_sensitive_information_before_converting,"")
B31: =template_label_b7_resource_use_circular_economy_and_waste_management_validation -> B7 - Resource use, circular economy and waste management | C31: =IF(D31=TRUE, template_label_classified_or_sensitive_information, IF(COUNTIF(C32:C34, template_label_error_plus_missing_value_plus_value_inconsistency) > 0, template_label_error_plus_missing_value_plus_value_inconsistency, IF(COUNTIF(C32:C34, template_label_error_plus_value_inconsistency) > 0, template_label_error_plus_value_inconsistency, IF(COUNTIF(C32:C34, template_label_error_plus_missing_value) > 0, template_label_error_plus_missing_value, IF(COUNTIF(C32:C34, template_label_error) > 0, template_label_error, IF(COUNTIF(C32:C34, template_label_missing_value_plus_value_inconsistency) > 0, template_label_missing_value_plus_value_inconsistency, IF(COUNTIF(C32:C34, template_label_value_inconsistency) > 0, template_label_value_inconsistency, IF(COUNTIF(C32:C34, template_label_missing_value) > 0, template_label_missing_value, IF(COUNTIF(C32:C34, template_label_ok) = ROWS(C32:C34), template_label_ok, IF(COUNTIF(C32:C34, "-") = ROWS(C32:C34), "-", IF(AND(COUNTIF(C32:C34,template_label_ok)>0, COUNTIF(C32:C34,template_label_error_plus_missing_value_plus_value_inconsistency)=0, COUNTIF(C32:C34,template_label_error_plus_value_inconsistency)=0, COUNTIF(C32:C34,template_label_error_plus_missing_value)=0, COUNTIF(C32:C34,template_label_error)=0, COUNTIF(C32:C34,template_label_missing_value_plus_value_inconsistency)=0, COUNTIF(C32:C34,template_label_value_inconsistency)=0, COUNTIF(C32:C34,template_label_missing_value)=0,OR(COUNTIF(C32:C34,template_label_missing_value)=0, COUNTIF(C32:C34,template_label_missing_value)>0)), template_label_ok, "-"))))))))) )) -> - | D31: =IF(COUNTIF(D33:D34,TRUE)=ROWS(D33:D34),TRUE,FALSE) -> FALSE
B32: =template_label_b7_description_of_circular_economy_principles -> B7 - Description of circular economy principles | C32: =IF(D32=TRUE, template_label_classified_or_sensitive_information, IF( AND( COUNTIF('Environmental Disclosures'!H316:I317, template_label_missing_value) > 0, COUNTIF('Environmental Disclosures'!H316:I317, template_label_value_inconsistency) = 0, COUNTIF('Environmental Disclosures'!H316:I317, template_label_ok) >= 0 ), template_label_missing_value, IF( AND( COUNTIF('Environmental Disclosures'!H316:I317, template_label_value_inconsistency) > 0, COUNTIF('Environmental Disclosures'!H316:I317, template_label_missing_value) = 0, COUNTIF('Environmental Disclosures'!H316:I317, template_label_ok) >= 0 ), template_label_value_inconsistency, IF( AND( COUNTIF('Environmental Disclosures'!H316:I317, template_label_value_inconsistency) > 0, COUNTIF('Environmental Disclosures'!H316:I317, template_label_missing_value) > 0, COUNTIF('Environmental Disclosures'!H316:I317, template_label_ok) >= 0 ), template_label_missing_value_plus_value_inconsistency, IF( AND( COUNTIF('Environmental Disclosures'!H316:I317, template_label_value_inconsistency) = 0, COUNTIF('Environmental Disclosures'!H316:I317, template_label_missing_value) = 0, COUNTIF('Environmental Disclosures'!H316:I317, template_label_ok) > 0 ), template_label_ok, "-" ) ) )) ) -> - | D32: FALSE | E32: =IF(AND(C32=template_label_classified_or_sensitive_information,COUNTIF('Environmental Disclosures'!D316:G317,"<>")>0),template_label_information_on_sensitive_information_before_converting,"")
B33: =template_label_b7_waste_generated -> B7 - Waste generated | C33: =IF(D33=TRUE, template_label_classified_or_sensitive_information, IF( AND( COUNTIF('Environmental Disclosures'!M323:M423, template_label_error) > 0, COUNTIF('Environmental Disclosures'!M323:M423, template_label_missing_value) > 0, COUNTIF('Environmental Disclosures'!M323:M423, template_label_value_inconsistency) > 0 ), template_label_error_plus_missing_value_plus_value_inconsistency, IF( AND( COUNTIF('Environmental Disclosures'!M323:M423, template_label_error) > 0, COUNTIF('Environmental Disclosures'!M323:M423, template_label_value_inconsistency) > 0, COUNTIF('Environmental Disclosures'!M323:M423, template_label_missing_value) = 0 ), template_label_error_plus_value_inconsistency, IF( AND( COUNTIF('Environmental Disclosures'!M323:M423, template_label_error) > 0, COUNTIF('Environmental Disclosures'!M323:M423, template_label_missing_value) > 0, COUNTIF('Environmental Disclosures'!M323:M423, template_label_value_inconsistency) = 0 ), template_label_error_plus_missing_value, IF( AND( COUNTIF('Environmental Disclosures'!M323:M423, template_label_missing_value) > 0, COUNTIF('Environmental Disclosures'!M323:M423, template_label_value_inconsistency) > 0, COUNTIF('Environmental Disclosures'!M323:M423, template_label_error) = 0 ), template_label_missing_value_plus_value_inconsistency, IF( AND( COUNTIF('Environmental Disclosures'!M323:M423, template_label_error) > 0, COUNTIF('Environmental Disclosures'!M323:M423, template_label_missing_value) = 0, COUNTIF('Environmental Disclosures'!M323:M423, template_label_value_inconsistency) = 0 ), template_label_error, IF( AND( COUNTIF('Environmental Disclosures'!M323:M423, template_label_missing_value) > 0, COUNTIF('Environmental Disclosures'!M323:M423, template_label_error) = 0, COUNTIF('Environmental Disclosures'!M323:M423, template_label_value_inconsistency) = 0 ), template_label_missing_value, IF( AND( COUNTIF('Environmental Disclosures'!M323:M423, template_label_value_inconsistency) > 0, COUNTIF('Environmental Disclosures'!M323:M423, template_label_error) = 0, COUNTIF('Environmental Disclosures'!M323:M423, template_label_missing_value) = 0 ), template_label_value_inconsistency, IF( AND( COUNTIF('Environmental Disclosures'!M323:M423, template_label_error) = 0, COUNTIF('Environmental Disclosures'!M323:M423, template_label_missing_value) = 0, COUNTIF('Environmental Disclosures'!M323:M423, template_label_value_inconsistency) = 0, COUNTIF('Environmental Disclosures'!M323:M423, template_label_ok) > 0 ), template_label_ok, "-" )))))))) ) -> - | D33: FALSE | E33: =IF(AND(C33=template_label_classified_or_sensitive_information,COUNTIF('Environmental Disclosures'!D323:K422,"<>")>0),template_label_information_on_sensitive_information_before_converting,"")
B34: =template_label_b7_annual_mass_flow_of_relevant_materials_used -> B7 - Annual mass-flow of relevant materials used | C34: =IF(D34=TRUE, template_label_classified_or_sensitive_information, IF(COUNTIF('Environmental Disclosures'!K435:K534, template_label_missing_value) > 0, template_label_missing_value, IF(COUNTIF('Environmental Disclosures'!K435:K534, template_label_ok) > 0, template_label_ok, "-")) ) -> - | D34: FALSE | E34: =IF(AND(C34=template_label_classified_or_sensitive_information,'Environmental Disclosures'!G433=TRUE),template_label_information_on_sensitive_information_before_converting,"")
B35: =template_label_social_disclosures_validation -> Social Disclosures
B36: =template_label_b8_workforce_general_characteristics_validation -> B8 - Workforce - General characteristics | C36: =IF(D36=TRUE, template_label_classified_or_sensitive_information, IF(COUNTIF(C37:C40, template_label_error_plus_missing_value_plus_value_inconsistency) > 0, template_label_error_plus_missing_value_plus_value_inconsistency, IF(COUNTIF(C37:C40, template_label_error_plus_value_inconsistency) > 0, template_label_error_plus_value_inconsistency, IF(COUNTIF(C37:C40, template_label_error_plus_missing_value) > 0, template_label_error_plus_missing_value, IF(COUNTIF(C37:C40, template_label_error) > 0, template_label_error, IF(COUNTIF(C37:C40, template_label_missing_value_plus_value_inconsistency) > 0, template_label_missing_value_plus_value_inconsistency, IF(COUNTIF(C37:C40, template_label_value_inconsistency) > 0, template_label_value_inconsistency, IF(COUNTIF(C37:C40, template_label_missing_value) > 0, template_label_missing_value, IF(COUNTIF(C37:C40, template_label_ok) = ROWS(C37:C40), template_label_ok, IF(COUNTIF(C37:C40, "-") = ROWS(C37:C40), "-", IF(AND(COUNTIF(C37:C40,template_label_ok)>0, COUNTIF(C37:C40,template_label_error_plus_missing_value_plus_value_inconsistency)=0, COUNTIF(C37:C40,template_label_error_plus_value_inconsistency)=0, COUNTIF(C37:C40,template_label_error_plus_missing_value)=0, COUNTIF(C37:C40,template_label_error)=0, COUNTIF(C37:C40,template_label_missing_value_plus_value_inconsistency)=0, COUNTIF(C37:C40,template_label_value_inconsistency)=0, COUNTIF(C37:C40,template_label_missing_value)=0,OR(COUNTIF(C37:C40,template_label_missing_value)=0, COUNTIF(C37:C40,template_label_missing_value)>0)), template_label_ok, "-"))))))))) )) -> - | D36: =IF(COUNTIF(D37:D40,TRUE)=ROWS(D37:D40),TRUE,FALSE) -> FALSE
B37: =template_label_b8_workforce_general_characteristics_type_of_contract -> B8 - Workforce - General characteristics - Type of contract | C37: =IF(D37=TRUE, template_label_classified_or_sensitive_information, IF(COUNTIF('Social Disclosures'!H10, template_label_missing_value) > 0, template_label_missing_value, IF(COUNTIF('Social Disclosures'!H10, template_label_ok) > 0, template_label_ok, "-")) ) -> - | D37: FALSE | E37: =IF(AND(C37=template_label_classified_or_sensitive_information,COUNTIF([0]!NumberOfPermanentContractEmployees,"<>")>0),template_label_information_on_sensitive_information_before_converting,"")
B38: =template_label_b8_workforce_general_characteristics_gender -> B8 - Workforce - General characteristics - Gender | C38: =IF(D38=TRUE,template_label_classified_or_sensitive_information, IF(COUNTIF('Social Disclosures'!H18,template_label_missing_value)>0, template_label_missing_value,IF(COUNTIF('Social Disclosures'!H18,template_label_value_inconsistency)>0, template_label_value_inconsistency, IF(COUNTIF('Social Disclosures'!H18,template_label_ok)>0, template_label_ok, "-")) )) -> - | D38: FALSE | E38: =IF(AND(C38=template_label_classified_or_sensitive_information,COUNTIF('Social Disclosures'!D18:G21,"<>")>0),template_label_information_on_sensitive_information_before_converting,"")
B39: =template_label_b8_workforce_general_characteristics_country_of_employment -> B8 - Workforce - General characteristics - Country of employment | C39: =IF(D39=TRUE, template_label_classified_or_sensitive_information, IF(COUNTIF('Social Disclosures'!I29:I128, template_label_missing_value) > 0, template_label_missing_value, IF(COUNTIF('Social Disclosures'!I29:I128, template_label_ok) > 0, template_label_ok, "-")) ) -> - | D39: FALSE | E39: =IF(AND(C39=template_label_classified_or_sensitive_information,'Social Disclosures'!E27=TRUE),template_label_information_on_sensitive_information_before_converting,"")
B40: =template_label_b8_workforce_general_characteristics_turnover_rate -> B8 - Workforce - General characteristics - Turnover rate | C40: =IF(D40=TRUE, template_label_classified_or_sensitive_information, IF(COUNTIF('Social Disclosures'!I134:I136, template_label_missing_value) > 0, template_label_missing_value, IF(COUNTIF('Social Disclosures'!I134:I136, template_label_ok) > 0, template_label_ok, "-")) ) -> - | D40: FALSE | E40: =IF(AND(C40=template_label_classified_or_sensitive_information,COUNTIF('Social Disclosures'!D134:H136,"<>")>0),template_label_information_on_sensitive_information_before_converting,"")
B41: =template_label_b9_workforce_health_and_safety_validation -> B9 - Workforce - Health and safety | C41: =IF(D41=TRUE, template_label_classified_or_sensitive_information, IF(COUNTIF('Social Disclosures'!I140:I144, template_label_missing_value) > 0, template_label_missing_value, IF(COUNTIF('Social Disclosures'!I140:I144, template_label_ok) > 0, template_label_ok, "-")) ) -> - | D41: FALSE | E41: =IF(AND(C41=template_label_classified_or_sensitive_information,COUNTIF('Social Disclosures'!D140:H142,"<>")>0),template_label_information_on_sensitive_information_before_converting,"")
...

Sheet General Information
A1: =template_label_paragraph_reference -> Paragraph Reference | B1: =template_label_paragraph_guidance_reference -> Paragraph Guidance Reference
C2: =template_label_information_on_the_report_necessary_for_xbrl & " " & template_label_always_to_be_reported -> Information on the report necessary for XBRL [Always to be reported]
C3: =template_label_name_of_the_reporting_entity -> Name of the reporting entity | F3: =IF(D3 = "", template_label_missing_value, template_label_ok) -> MISSING VALUE
C4: =template_label_identifier_of_the_reporting_entity -> Identifier of the reporting entity (select and specify on the right) | F4: =IF(OR(D4 = "", E4 = ""), template_label_missing_value, template_label_ok) -> MISSING VALUE | G4: =template_label_identifier_warning -> ℹ️ The entity identifier is a unique ID, that will enable identifying the company that has reported the information. The VSME Standard does not require any specific identifier. An entity identifier is required for the digital reporting.
C5: =template_label_currency_of_the_monetary_values_in_the_report -> Currency of the monetary values in the report | F5: =IF(D5 = "", template_label_missing_value, template_label_ok) -> MISSING VALUE
C6: =template_label_starting_year -> Starting year | F6: =IF(OR(D6 = "", D7 = "", D8 = ""), template_label_missing_value, IF(OR( AND(D7 = 2, D8 > 29), AND(D7 = 2, D8 = 29, NOT(AND(MOD(D6, 4) = 0, OR(MOD(D6, 100) <> 0, MOD(D6, 400) = 0)))), AND(OR(D7 = 4, D7 = 6, D7 = 9, D7 = 11), D8 = 31) ), template_label_error, IF(F10 = template_label_value_inconsistency, template_label_value_inconsistency, template_label_ok) ) ) -> MISSING VALUE | G6: =template_label_date_warning -> ℹ️ If VALUE INCONSISTENCY message appears on the right, please ensure that the reporting period end date is greater than the reporting period start date.
C7: =template_label_starting_month -> Starting month
C8: =template_label_starting_day -> Starting day
C9: =template_label_reporting_period_start_date -> Reporting period start date (yyyy-mm-dd) | D9: =IF(OR(ISBLANK(D6), ISBLANK(D7), ISBLANK(D8)), "-", D6 & "-" & TEXT(D7, "00") & "-" & TEXT(D8, "00")) -> -
C10: =template_label_ending_year -> Ending year | F10: =IF(OR(D10 = "", D11 = "", D12 = ""), template_label_missing_value, IF(OR( AND(D11 = 2, D12 > 29), AND(D11 = 2, D12 = 29, NOT(AND(MOD(D10, 4) = 0, OR(MOD(D10, 100) <> 0, MOD(D10, 400) = 0)))), AND(OR(D11 = 4, D11 = 6, D11 = 9, D11 = 11), D12 = 31) ), template_label_error, IF(D10 < D6, template_label_value_inconsistency, IF(D10 > D6, template_label_ok, IF(AND(D10 = D6, MATCH(D11, {1;2;3;4;5;6;7;8;9;10;11;12}, 0) < MATCH(D7, {1;2;3;4;5;6;7;8;9;10;11;12}, 0)), template_label_value_inconsistency, IF(AND(D10 = D6, MATCH(D11, {1;2;3;4;5;6;7;8;9;10;11;12}, 0) > MATCH(D7, {1;2;3;4;5;6;7;8;9;10;11;12}, 0)), template_label_ok, IF(AND(D10 = D6, MATCH(D11, {1;2;3;4;5;6;7;8;9;10;11;12}, 0) = MATCH(D7, {1;2;3;4;5;6;7;8;9;10;11;12}, 0), D12 < D8), template_label_value_inconsistency, template_label_ok ))))))) -> MISSING VALUE | G10: =template_label_date_warning -> ℹ️ If VALUE INCONSISTENCY message appears on the right, please ensure that the reporting period end date is greater than the reporting period start date.
C11: =template_label_ending_month -> Ending month
C12: Ending day
C13: =template_label_reporting_period_end_date -> Reporting period end date (yyyy-mm-dd) | D13: =IF(OR(ISBLANK(D10), ISBLANK(D11), ISBLANK(D12)), "-", D10 & "-" & TEXT(D11, "00") & "-" & TEXT(D12, "00")) -> -
C16: =template_label_information_on_previous_reporting_period -> Information on previous reporting period
C17: 16
C18: =template_label_disclosures_from_the_previous_reporting_period_that_remain_unchanged -> This report contains disclosures from the previous reporting period that remain unchanged | E18: FALSE | F18: =IF(E18 = FALSE, "", template_label_ok)
C19: =template_label_disclosures_for_which_no_changes_are_reported_compared_to_the_previous_period_reporting -> List of disclosures for which no changes are reported compared to the previous period reporting | F19: =IF(AND(E18 = FALSE, E19 = ""), "", IF(AND(E18 = FALSE, E19 <> ""), "", IF(AND(E18 = TRUE, E19 = ""), template_label_missing_value, IF(AND(E18 = TRUE, E19 <> "", COUNTIF(E19:E118, E19) = COUNTA(E19:E118), COUNTA(E19:E118) > 1), template_label_value_inconsistency, template_label_ok)))) | G19: =template_label_additional_rows_warning -> ℹ️ Lists can be expanded using the little [+] button on the left. If the number of rows is not sufficient, those can be added by right clicking the second row and selecting "Insert row".
F20: =IF($E$18 = FALSE, "", IF(E20 = "", "", IF(COUNTIF($E$19:$E$118, E20) > 1, template_label_value_inconsistency, template_label_ok)))
F21: =IF($E$18 = FALSE, "", IF(E21 = "", "", IF(COUNTIF($E$19:$E$118, E21) > 1, template_label_value_inconsistency, template_label_ok)))
F22: =IF($E$18 = FALSE, "", IF(E22 = "", "", IF(COUNTIF($E$19:$E$118, E22) > 1, template_label_value_inconsistency, template_label_ok)))
F23: =IF($E$18 = FALSE, "", IF(E23 = "", "", IF(COUNTIF($E$19:$E$118, E23) > 1, template_label_value_inconsistency, template_label_ok)))
F24: =IF($E$18 = FALSE, "", IF(E24 = "", "", IF(COUNTIF($E$19:$E$118, E24) > 1, template_label_value_inconsistency, template_label_ok)))
F25: =IF($E$18 = FALSE, "", IF(E25 = "", "", IF(COUNTIF($E$19:$E$118, E25) > 1, template_label_value_inconsistency, template_label_ok)))
F26: =IF($E$18 = FALSE, "", IF(E26 = "", "", IF(COUNTIF($E$19:$E$118, E26) > 1, template_label_value_inconsistency, template_label_ok)))
F27: =IF($E$18 = FALSE, "", IF(E27 = "", "", IF(COUNTIF($E$19:$E$118, E27) > 1, template_label_value_inconsistency, template_label_ok)))
C119: =template_label_link_to_previous_report_containing_disclosures_that_remain_unchanged -> Link to previous report containing disclosures that remain unchanged | F119: =IF(AND(E18 = FALSE, E119 = ""), "", IF(AND(E18 = TRUE, E119 = ""), template_label_missing_value, IF(AND(E18 = FALSE, E119 <> ""), "", IF(AND(E18 = TRUE, E119 <> "", OR(LEFT(E119, 7) = "http://", LEFT(E119, 8) = "https://", LEFT(E119, 4) = "www.")), template_label_ok, IF(E18 = TRUE, template_label_invalid_url, template_label_missing_value)))))
C121: =template_label_b1_basis_for_preparation & " " & template_label_from & " " & template_starting_date_display & " " & template_label_to & " " & template_ending_date_display & " " & template_label_always_to_be_reported -> B1 - Basis for Preparation & Module from - to - [Always to be reported]
A122: 24(a) | B122: N/A | C122: =template_label_basis_for_preparation -> Basis for preparation (Basic Module Only or Basic & Comprehensive Module) | F122: =IF( 'Table of Contents & Validation'!D11=TRUE, IF(E122 = "", "", template_label_ok), IF(E122 = "", template_label_missing_value, template_label_ok) ) -> MISSING VALUE
A123: 24(b) | B123: N/A | C123: =template_label_list_of_omitted_disclosures_deemed_to_be_classified_or_sensitive_information -> List of omitted disclosures deemed to be classified or sensitive information | E123: =IF('Technical Sheet'!E167=0,template_label_none,_xlfn.XLOOKUP('Technical Sheet'!A28, 'Technical Sheet'!E106:E166, 'Table of Contents & Validation'!B10:B70, "")) -> None | G123: =template_label_bold_omitted_information -> ℹ️ Whenever a disclosure is fully omitted because sensitive or classfied, it will be highligted in bold
E124: =_xlfn.XLOOKUP('Technical Sheet'!A29, 'Technical Sheet'!E107:E167, 'Table of Contents & Validation'!B11:B71, "")
E125: =_xlfn.XLOOKUP('Technical Sheet'!A30, 'Technical Sheet'!E108:E168, 'Table of Contents & Validation'!B12:B72, "")
E126: =_xlfn.XLOOKUP('Technical Sheet'!A31, 'Technical Sheet'!E109:E169, 'Table of Contents & Validation'!B13:B73, "")
E127: =_xlfn.XLOOKUP('Technical Sheet'!A32, 'Technical Sheet'!E110:E170, 'Table of Contents & Validation'!B14:B74, "")
E128: =_xlfn.XLOOKUP('Technical Sheet'!A33, 'Technical Sheet'!E111:E171, 'Table of Contents & Validation'!B15:B75, "")
E129: =_xlfn.XLOOKUP('Technical Sheet'!A34, 'Technical Sheet'!E112:E172, 'Table of Contents & Validation'!B16:B76, "")
E130: =_xlfn.XLOOKUP('Technical Sheet'!A35, 'Technical Sheet'!E112:E173, 'Table of Contents & Validation'!B16:B77, "")
E131: =_xlfn.XLOOKUP('Technical Sheet'!A36, 'Technical Sheet'!E113:E174, 'Table of Contents & Validation'!B17:B78, "")
E132: =_xlfn.XLOOKUP('Technical Sheet'!A37, 'Technical Sheet'!E114:E175, 'Table of Contents & Validation'!B18:B79, "")
E133: =_xlfn.XLOOKUP('Technical Sheet'!A38, 'Technical Sheet'!E115:E176, 'Table of Contents & Validation'!B19:B80, "")
E134: =_xlfn.XLOOKUP('Technical Sheet'!A39, 'Technical Sheet'!E116:E177, 'Table of Contents & Validation'!B20:B81, "")
...

Sheet Environmental Disclosures
A1: =template_label_paragraph_reference -> Paragraph Reference | B1: =template_label_paragraph_guidance_reference -> Paragraph Guidance Reference
C2: =template_label_b3_total_energy_consumption&" "&template_label_from&" "&template_starting_date_display&" "&template_label_to&" "&template_ending_date_display&" "&template_label_always_to_be_reported -> B3 - Total Energy Consumption (in MWh) from - to - [Always to be reported]
C3: 29
C4: 18-25
